[2025-02-07T06:10:47.209+0000] {taskinstance.py:1125} INFO - Dependencies all met for dep_context=non-requeueable deps ti=<TaskInstance: get_current_weather.transform_raw_data scheduled__2025-02-06T00:00:00+00:00 [queued]>
[2025-02-07T06:10:47.220+0000] {taskinstance.py:1125} INFO - Dependencies all met for dep_context=requeueable deps ti=<TaskInstance: get_current_weather.transform_raw_data scheduled__2025-02-06T00:00:00+00:00 [queued]>
[2025-02-07T06:10:47.222+0000] {taskinstance.py:1331} INFO - Starting attempt 1 of 1
[2025-02-07T06:10:47.238+0000] {taskinstance.py:1350} INFO - Executing <Task(PythonOperator): transform_raw_data> on 2025-02-06 00:00:00+00:00
[2025-02-07T06:10:47.242+0000] {standard_task_runner.py:57} INFO - Started process 138 to run task
[2025-02-07T06:10:47.246+0000] {standard_task_runner.py:84} INFO - Running: ['***', 'tasks', 'run', 'get_current_weather', 'transform_raw_data', 'scheduled__2025-02-06T00:00:00+00:00', '--job-id', '5', '--raw', '--subdir', 'DAGS_FOLDER/weather_data_dag.py', '--cfg-path', '/tmp/tmpjkx7vmi_']
[2025-02-07T06:10:47.262+0000] {standard_task_runner.py:85} INFO - Job 5: Subtask transform_raw_data
[2025-02-07T06:10:47.356+0000] {task_command.py:410} INFO - Running <TaskInstance: get_current_weather.transform_raw_data scheduled__2025-02-06T00:00:00+00:00 [running]> on host 5a15db971c3c
[2025-02-07T06:10:47.520+0000] {taskinstance.py:1568} INFO - Exporting env vars: AIRFLOW_CTX_DAG_OWNER='airscholar' AIRFLOW_CTX_DAG_ID='get_current_weather' AIRFLOW_CTX_TASK_ID='transform_raw_data' AIRFLOW_CTX_EXECUTION_DATE='2025-02-06T00:00:00+00:00' AIRFLOW_CTX_TRY_NUMBER='1' AIRFLOW_CTX_DAG_RUN_ID='scheduled__2025-02-06T00:00:00+00:00'
[2025-02-07T06:10:47.523+0000] {taskinstance.py:1847} ERROR - Task failed with exception
Traceback (most recent call last):
  File "/home/airflow/.local/lib/python3.9/site-packages/airflow/operators/python.py", line 181, in execute
    return_value = self.execute_callable()
  File "/home/airflow/.local/lib/python3.9/site-packages/airflow/operators/python.py", line 198, in execute_callable
    return self.python_callable(*self.op_args, **self.op_kwargs)
TypeError: transform() missing 1 required positional argument: 'df'
[2025-02-07T06:10:47.542+0000] {taskinstance.py:1368} INFO - Marking task as FAILED. dag_id=get_current_weather, task_id=transform_raw_data, execution_date=20250206T000000, start_date=20250207T061047, end_date=20250207T061047
[2025-02-07T06:10:47.576+0000] {standard_task_runner.py:104} ERROR - Failed to execute job 5 for task transform_raw_data (transform() missing 1 required positional argument: 'df'; 138)
[2025-02-07T06:10:47.602+0000] {local_task_job_runner.py:232} INFO - Task exited with return code 1
[2025-02-07T06:10:47.639+0000] {taskinstance.py:2674} INFO - 0 downstream tasks scheduled from follow-on schedule check
