[2025-02-14T22:38:01.688+0000] {taskinstance.py:1125} INFO - Dependencies all met for dep_context=non-requeueable deps ti=<TaskInstance: weather_data_ETL.get_location_dict manual__2025-02-14T22:37:54.095882+00:00 [queued]>
[2025-02-14T22:38:01.704+0000] {taskinstance.py:1125} INFO - Dependencies all met for dep_context=requeueable deps ti=<TaskInstance: weather_data_ETL.get_location_dict manual__2025-02-14T22:37:54.095882+00:00 [queued]>
[2025-02-14T22:38:01.705+0000] {taskinstance.py:1331} INFO - Starting attempt 1 of 1
[2025-02-14T22:38:01.729+0000] {taskinstance.py:1350} INFO - Executing <Task(PythonOperator): get_location_dict> on 2025-02-14 22:37:54.095882+00:00
[2025-02-14T22:38:01.736+0000] {standard_task_runner.py:57} INFO - Started process 160 to run task
[2025-02-14T22:38:01.743+0000] {standard_task_runner.py:84} INFO - Running: ['***', 'tasks', 'run', 'weather_data_ETL', 'get_location_dict', 'manual__2025-02-14T22:37:54.095882+00:00', '--job-id', '40', '--raw', '--subdir', 'DAGS_FOLDER/weather_data_dag.py', '--cfg-path', '/tmp/tmpiakhvqo2']
[2025-02-14T22:38:01.747+0000] {standard_task_runner.py:85} INFO - Job 40: Subtask get_location_dict
[2025-02-14T22:38:01.872+0000] {task_command.py:410} INFO - Running <TaskInstance: weather_data_ETL.get_location_dict manual__2025-02-14T22:37:54.095882+00:00 [running]> on host 2079ceed134c
[2025-02-14T22:38:02.072+0000] {taskinstance.py:1568} INFO - Exporting env vars: AIRFLOW_CTX_DAG_OWNER='airscholar' AIRFLOW_CTX_DAG_ID='weather_data_ETL' AIRFLOW_CTX_TASK_ID='get_location_dict' AIRFLOW_CTX_EXECUTION_DATE='2025-02-14T22:37:54.095882+00:00' AIRFLOW_CTX_TRY_NUMBER='1' AIRFLOW_CTX_DAG_RUN_ID='manual__2025-02-14T22:37:54.095882+00:00'
[2025-02-14T22:38:02.082+0000] {taskinstance.py:1847} ERROR - Task failed with exception
Traceback (most recent call last):
  File "/home/airflow/.local/lib/python3.9/site-packages/airflow/operators/python.py", line 181, in execute
    return_value = self.execute_callable()
  File "/home/airflow/.local/lib/python3.9/site-packages/airflow/operators/python.py", line 198, in execute_callable
    return self.python_callable(*self.op_args, **self.op_kwargs)
  File "/opt/airflow/dags/utils.py", line 13, in get_location_dict
    conn = psycopg2.connect(**DB_CONFIG)
  File "/home/airflow/.local/lib/python3.9/site-packages/psycopg2/__init__.py", line 122, in connect
    conn = _connect(dsn, connection_factory=connection_factory, **kwasync)
psycopg2.OperationalError: connection to server at "postgres-dev" (172.23.0.2), port 5432 failed: FATAL:  database "ski_weather" does not exist

[2025-02-14T22:38:02.108+0000] {taskinstance.py:1368} INFO - Marking task as FAILED. dag_id=weather_data_ETL, task_id=get_location_dict, execution_date=20250214T223754, start_date=20250214T223801, end_date=20250214T223802
[2025-02-14T22:38:02.140+0000] {standard_task_runner.py:104} ERROR - Failed to execute job 40 for task get_location_dict (connection to server at "postgres-dev" (172.23.0.2), port 5432 failed: FATAL:  database "ski_weather" does not exist
; 160)
[2025-02-14T22:38:02.156+0000] {local_task_job_runner.py:232} INFO - Task exited with return code 1
[2025-02-14T22:38:02.219+0000] {taskinstance.py:2674} INFO - 0 downstream tasks scheduled from follow-on schedule check
