[2025-02-10T22:01:55.814+0000] {taskinstance.py:1125} INFO - Dependencies all met for dep_context=non-requeueable deps ti=<TaskInstance: get_current_weather.load_data_from_api scheduled__2025-02-09T00:00:00+00:00 [queued]>
[2025-02-10T22:01:55.827+0000] {taskinstance.py:1125} INFO - Dependencies all met for dep_context=requeueable deps ti=<TaskInstance: get_current_weather.load_data_from_api scheduled__2025-02-09T00:00:00+00:00 [queued]>
[2025-02-10T22:01:55.828+0000] {taskinstance.py:1331} INFO - Starting attempt 1 of 1
[2025-02-10T22:01:55.846+0000] {taskinstance.py:1350} INFO - Executing <Task(PythonOperator): load_data_from_api> on 2025-02-09 00:00:00+00:00
[2025-02-10T22:01:55.853+0000] {standard_task_runner.py:57} INFO - Started process 28379 to run task
[2025-02-10T22:01:55.857+0000] {standard_task_runner.py:84} INFO - Running: ['***', 'tasks', 'run', 'get_current_weather', 'load_data_from_api', 'scheduled__2025-02-09T00:00:00+00:00', '--job-id', '13', '--raw', '--subdir', 'DAGS_FOLDER/weather_data_dag.py', '--cfg-path', '/tmp/tmpjsuj3v9a']
[2025-02-10T22:01:55.860+0000] {standard_task_runner.py:85} INFO - Job 13: Subtask load_data_from_api
[2025-02-10T22:01:55.985+0000] {task_command.py:410} INFO - Running <TaskInstance: get_current_weather.load_data_from_api scheduled__2025-02-09T00:00:00+00:00 [running]> on host 5a15db971c3c
[2025-02-10T22:01:56.171+0000] {taskinstance.py:1568} INFO - Exporting env vars: AIRFLOW_CTX_DAG_OWNER='airscholar' AIRFLOW_CTX_DAG_ID='get_current_weather' AIRFLOW_CTX_TASK_ID='load_data_from_api' AIRFLOW_CTX_EXECUTION_DATE='2025-02-09T00:00:00+00:00' AIRFLOW_CTX_TRY_NUMBER='1' AIRFLOW_CTX_DAG_RUN_ID='scheduled__2025-02-09T00:00:00+00:00'
[2025-02-10T22:01:56.199+0000] {taskinstance.py:1847} ERROR - Task failed with exception
Traceback (most recent call last):
  File "/home/airflow/.local/lib/python3.9/site-packages/urllib3/connection.py", line 174, in _new_conn
    conn = connection.create_connection(
  File "/home/airflow/.local/lib/python3.9/site-packages/urllib3/util/connection.py", line 72, in create_connection
    for res in socket.getaddrinfo(host, port, family, socket.SOCK_STREAM):
  File "/usr/local/lib/python3.9/socket.py", line 954, in getaddrinfo
    for res in _socket.getaddrinfo(host, port, family, type, proto, flags):
socket.gaierror: [Errno -2] Name or service not known

During handling of the above exception, another exception occurred:

Traceback (most recent call last):
  File "/home/airflow/.local/lib/python3.9/site-packages/urllib3/connectionpool.py", line 703, in urlopen
    httplib_response = self._make_request(
  File "/home/airflow/.local/lib/python3.9/site-packages/urllib3/connectionpool.py", line 398, in _make_request
    conn.request(method, url, **httplib_request_kw)
  File "/home/airflow/.local/lib/python3.9/site-packages/urllib3/connection.py", line 244, in request
    super(HTTPConnection, self).request(method, url, body=body, headers=headers)
  File "/usr/local/lib/python3.9/http/client.py", line 1285, in request
    self._send_request(method, url, body, headers, encode_chunked)
  File "/usr/local/lib/python3.9/http/client.py", line 1331, in _send_request
    self.endheaders(body, encode_chunked=encode_chunked)
  File "/usr/local/lib/python3.9/http/client.py", line 1280, in endheaders
    self._send_output(message_body, encode_chunked=encode_chunked)
  File "/usr/local/lib/python3.9/http/client.py", line 1040, in _send_output
    self.send(msg)
  File "/usr/local/lib/python3.9/http/client.py", line 980, in send
    self.connect()
  File "/home/airflow/.local/lib/python3.9/site-packages/urllib3/connection.py", line 205, in connect
    conn = self._new_conn()
  File "/home/airflow/.local/lib/python3.9/site-packages/urllib3/connection.py", line 186, in _new_conn
    raise NewConnectionError(
urllib3.exceptions.NewConnectionError: <urllib3.connection.HTTPConnection object at 0x7f9570ca8610>: Failed to establish a new connection: [Errno -2] Name or service not known

During handling of the above exception, another exception occurred:

Traceback (most recent call last):
  File "/home/airflow/.local/lib/python3.9/site-packages/requests/adapters.py", line 487, in send
    resp = conn.urlopen(
  File "/home/airflow/.local/lib/python3.9/site-packages/urllib3/connectionpool.py", line 787, in urlopen
    retries = retries.increment(
  File "/home/airflow/.local/lib/python3.9/site-packages/urllib3/util/retry.py", line 592, in increment
    raise MaxRetryError(_pool, url, error or ResponseError(cause))
urllib3.exceptions.MaxRetryError: HTTPConnectionPool(host='api.openweathermap.org', port=80): Max retries exceeded with url: /data/2.5/weather?lat=39.87652886804281&lon=-105.76577005628859&appid=None (Caused by NewConnectionError('<urllib3.connection.HTTPConnection object at 0x7f9570ca8610>: Failed to establish a new connection: [Errno -2] Name or service not known'))

During handling of the above exception, another exception occurred:

Traceback (most recent call last):
  File "/home/airflow/.local/lib/python3.9/site-packages/airflow/operators/python.py", line 181, in execute
    return_value = self.execute_callable()
  File "/home/airflow/.local/lib/python3.9/site-packages/airflow/operators/python.py", line 198, in execute_callable
    return self.python_callable(*self.op_args, **self.op_kwargs)
  File "/opt/airflow/dags/get_current_weather.py", line 14, in load_data_from_api
    response = requests.get(url)
  File "/home/airflow/.local/lib/python3.9/site-packages/requests/api.py", line 73, in get
    return request("get", url, params=params, **kwargs)
  File "/home/airflow/.local/lib/python3.9/site-packages/requests/api.py", line 59, in request
    return session.request(method=method, url=url, **kwargs)
  File "/home/airflow/.local/lib/python3.9/site-packages/requests/sessions.py", line 587, in request
    resp = self.send(prep, **send_kwargs)
  File "/home/airflow/.local/lib/python3.9/site-packages/requests/sessions.py", line 701, in send
    r = adapter.send(request, **kwargs)
  File "/home/airflow/.local/lib/python3.9/site-packages/requests/adapters.py", line 520, in send
    raise ConnectionError(e, request=request)
requests.exceptions.ConnectionError: HTTPConnectionPool(host='api.openweathermap.org', port=80): Max retries exceeded with url: /data/2.5/weather?lat=39.87652886804281&lon=-105.76577005628859&appid=None (Caused by NewConnectionError('<urllib3.connection.HTTPConnection object at 0x7f9570ca8610>: Failed to establish a new connection: [Errno -2] Name or service not known'))
[2025-02-10T22:01:56.237+0000] {taskinstance.py:1368} INFO - Marking task as FAILED. dag_id=get_current_weather, task_id=load_data_from_api, execution_date=20250209T000000, start_date=20250210T220155, end_date=20250210T220156
[2025-02-10T22:01:56.261+0000] {standard_task_runner.py:104} ERROR - Failed to execute job 13 for task load_data_from_api (HTTPConnectionPool(host='api.openweathermap.org', port=80): Max retries exceeded with url: /data/2.5/weather?lat=39.87652886804281&lon=-105.76577005628859&appid=None (Caused by NewConnectionError('<urllib3.connection.HTTPConnection object at 0x7f9570ca8610>: Failed to establish a new connection: [Errno -2] Name or service not known')); 28379)
[2025-02-10T22:01:56.276+0000] {local_task_job_runner.py:232} INFO - Task exited with return code 1
[2025-02-10T22:01:56.323+0000] {taskinstance.py:2674} INFO - 0 downstream tasks scheduled from follow-on schedule check
