[2025-02-14T22:43:20.565+0000] {taskinstance.py:1125} INFO - Dependencies all met for dep_context=non-requeueable deps ti=<TaskInstance: weather_data_ETL.transform_weather manual__2025-02-14T22:42:46.653678+00:00 [queued]>
[2025-02-14T22:43:20.578+0000] {taskinstance.py:1125} INFO - Dependencies all met for dep_context=requeueable deps ti=<TaskInstance: weather_data_ETL.transform_weather manual__2025-02-14T22:42:46.653678+00:00 [queued]>
[2025-02-14T22:43:20.579+0000] {taskinstance.py:1331} INFO - Starting attempt 1 of 1
[2025-02-14T22:43:20.599+0000] {taskinstance.py:1350} INFO - Executing <Task(PythonOperator): transform_weather> on 2025-02-14 22:42:46.653678+00:00
[2025-02-14T22:43:20.605+0000] {standard_task_runner.py:57} INFO - Started process 234 to run task
[2025-02-14T22:43:20.609+0000] {standard_task_runner.py:84} INFO - Running: ['***', 'tasks', 'run', 'weather_data_ETL', 'transform_weather', 'manual__2025-02-14T22:42:46.653678+00:00', '--job-id', '44', '--raw', '--subdir', 'DAGS_FOLDER/weather_data_dag.py', '--cfg-path', '/tmp/tmpta83ppgc']
[2025-02-14T22:43:20.613+0000] {standard_task_runner.py:85} INFO - Job 44: Subtask transform_weather
[2025-02-14T22:43:20.728+0000] {task_command.py:410} INFO - Running <TaskInstance: weather_data_ETL.transform_weather manual__2025-02-14T22:42:46.653678+00:00 [running]> on host 2079ceed134c
[2025-02-14T22:43:20.916+0000] {taskinstance.py:1568} INFO - Exporting env vars: AIRFLOW_CTX_DAG_OWNER='airscholar' AIRFLOW_CTX_DAG_ID='weather_data_ETL' AIRFLOW_CTX_TASK_ID='transform_weather' AIRFLOW_CTX_EXECUTION_DATE='2025-02-14T22:42:46.653678+00:00' AIRFLOW_CTX_TRY_NUMBER='1' AIRFLOW_CTX_DAG_RUN_ID='manual__2025-02-14T22:42:46.653678+00:00'
[2025-02-14T22:43:20.994+0000] {taskinstance.py:1847} ERROR - Task failed with exception
Traceback (most recent call last):
  File "/home/airflow/.local/lib/python3.9/site-packages/airflow/operators/python.py", line 181, in execute
    return_value = self.execute_callable()
  File "/home/airflow/.local/lib/python3.9/site-packages/airflow/operators/python.py", line 198, in execute_callable
    return self.python_callable(*self.op_args, **self.op_kwargs)
  File "/opt/airflow/dags/transform_weather.py", line 12, in transform_resort_weather_response_data
    transformed_response = transform_response_data(response)
  File "/opt/airflow/dags/transform_weather.py", line 21, in transform_response_data
    alerts = get_alerts(response)
  File "/opt/airflow/dags/transform_weather.py", line 99, in get_alerts
    data = {key: alerts_cols(alert.get(key, 0)) for key in alerts_cols}
  File "/opt/airflow/dags/transform_weather.py", line 99, in <dictcomp>
    data = {key: alerts_cols(alert.get(key, 0)) for key in alerts_cols}
TypeError: 'dict' object is not callable
[2025-02-14T22:43:21.013+0000] {taskinstance.py:1368} INFO - Marking task as FAILED. dag_id=weather_data_ETL, task_id=transform_weather, execution_date=20250214T224246, start_date=20250214T224320, end_date=20250214T224321
[2025-02-14T22:43:21.034+0000] {standard_task_runner.py:104} ERROR - Failed to execute job 44 for task transform_weather ('dict' object is not callable; 234)
[2025-02-14T22:43:21.064+0000] {local_task_job_runner.py:232} INFO - Task exited with return code 1
[2025-02-14T22:43:21.106+0000] {taskinstance.py:2674} INFO - 0 downstream tasks scheduled from follow-on schedule check
