[2025-02-15T01:47:16.646+0000] {taskinstance.py:1125} INFO - Dependencies all met for dep_context=non-requeueable deps ti=<TaskInstance: weather_data_ETL.get_location_dict manual__2025-02-15T01:47:12.123974+00:00 [queued]>
[2025-02-15T01:47:16.659+0000] {taskinstance.py:1125} INFO - Dependencies all met for dep_context=requeueable deps ti=<TaskInstance: weather_data_ETL.get_location_dict manual__2025-02-15T01:47:12.123974+00:00 [queued]>
[2025-02-15T01:47:16.660+0000] {taskinstance.py:1331} INFO - Starting attempt 1 of 1
[2025-02-15T01:47:16.679+0000] {taskinstance.py:1350} INFO - Executing <Task(PythonOperator): get_location_dict> on 2025-02-15 01:47:12.123974+00:00
[2025-02-15T01:47:16.685+0000] {standard_task_runner.py:57} INFO - Started process 266 to run task
[2025-02-15T01:47:16.692+0000] {standard_task_runner.py:84} INFO - Running: ['***', 'tasks', 'run', 'weather_data_ETL', 'get_location_dict', 'manual__2025-02-15T01:47:12.123974+00:00', '--job-id', '81', '--raw', '--subdir', 'DAGS_FOLDER/weather_dag.py', '--cfg-path', '/tmp/tmpq54kqenn']
[2025-02-15T01:47:16.694+0000] {standard_task_runner.py:85} INFO - Job 81: Subtask get_location_dict
[2025-02-15T01:47:16.811+0000] {task_command.py:410} INFO - Running <TaskInstance: weather_data_ETL.get_location_dict manual__2025-02-15T01:47:12.123974+00:00 [running]> on host 184396a03990
[2025-02-15T01:47:17.021+0000] {taskinstance.py:1568} INFO - Exporting env vars: AIRFLOW_CTX_DAG_OWNER='airscholar' AIRFLOW_CTX_DAG_ID='weather_data_ETL' AIRFLOW_CTX_TASK_ID='get_location_dict' AIRFLOW_CTX_EXECUTION_DATE='2025-02-15T01:47:12.123974+00:00' AIRFLOW_CTX_TRY_NUMBER='1' AIRFLOW_CTX_DAG_RUN_ID='manual__2025-02-15T01:47:12.123974+00:00'
[2025-02-15T01:47:17.035+0000] {taskinstance.py:1847} ERROR - Task failed with exception
Traceback (most recent call last):
  File "/home/airflow/.local/lib/python3.9/site-packages/airflow/operators/python.py", line 181, in execute
    return_value = self.execute_callable()
  File "/home/airflow/.local/lib/python3.9/site-packages/airflow/operators/python.py", line 198, in execute_callable
    return self.python_callable(*self.op_args, **self.op_kwargs)
  File "/opt/airflow/dags/utils.py", line 13, in get_location_dict
    conn = psycopg2.connect(**DB_CONFIG)
  File "/home/airflow/.local/lib/python3.9/site-packages/psycopg2/__init__.py", line 122, in connect
    conn = _connect(dsn, connection_factory=connection_factory, **kwasync)
psycopg2.OperationalError: could not translate host name "postgres-dev" to address: Name or service not known

[2025-02-15T01:47:17.068+0000] {taskinstance.py:1368} INFO - Marking task as FAILED. dag_id=weather_data_ETL, task_id=get_location_dict, execution_date=20250215T014712, start_date=20250215T014716, end_date=20250215T014717
[2025-02-15T01:47:17.097+0000] {standard_task_runner.py:104} ERROR - Failed to execute job 81 for task get_location_dict (could not translate host name "postgres-dev" to address: Name or service not known
; 266)
[2025-02-15T01:47:17.107+0000] {local_task_job_runner.py:232} INFO - Task exited with return code 1
[2025-02-15T01:47:17.156+0000] {taskinstance.py:2674} INFO - 0 downstream tasks scheduled from follow-on schedule check
