[2025-02-15T01:50:36.361+0000] {taskinstance.py:1125} INFO - Dependencies all met for dep_context=non-requeueable deps ti=<TaskInstance: weather_data_ETL.load_weather manual__2025-02-15T01:50:23.485590+00:00 [queued]>
[2025-02-15T01:50:36.376+0000] {taskinstance.py:1125} INFO - Dependencies all met for dep_context=requeueable deps ti=<TaskInstance: weather_data_ETL.load_weather manual__2025-02-15T01:50:23.485590+00:00 [queued]>
[2025-02-15T01:50:36.377+0000] {taskinstance.py:1331} INFO - Starting attempt 1 of 1
[2025-02-15T01:50:36.398+0000] {taskinstance.py:1350} INFO - Executing <Task(PythonOperator): load_weather> on 2025-02-15 01:50:23.485590+00:00
[2025-02-15T01:50:36.407+0000] {standard_task_runner.py:57} INFO - Started process 49 to run task
[2025-02-15T01:50:36.412+0000] {standard_task_runner.py:84} INFO - Running: ['***', 'tasks', 'run', 'weather_data_ETL', 'load_weather', 'manual__2025-02-15T01:50:23.485590+00:00', '--job-id', '85', '--raw', '--subdir', 'DAGS_FOLDER/weather_dag.py', '--cfg-path', '/tmp/tmp0v4m1tgi']
[2025-02-15T01:50:36.416+0000] {standard_task_runner.py:85} INFO - Job 85: Subtask load_weather
[2025-02-15T01:50:36.551+0000] {task_command.py:410} INFO - Running <TaskInstance: weather_data_ETL.load_weather manual__2025-02-15T01:50:23.485590+00:00 [running]> on host cbea98f91475
[2025-02-15T01:50:36.804+0000] {taskinstance.py:1568} INFO - Exporting env vars: AIRFLOW_CTX_DAG_OWNER='airscholar' AIRFLOW_CTX_DAG_ID='weather_data_ETL' AIRFLOW_CTX_TASK_ID='load_weather' AIRFLOW_CTX_EXECUTION_DATE='2025-02-15T01:50:23.485590+00:00' AIRFLOW_CTX_TRY_NUMBER='1' AIRFLOW_CTX_DAG_RUN_ID='manual__2025-02-15T01:50:23.485590+00:00'
[2025-02-15T01:50:36.876+0000] {taskinstance.py:1847} ERROR - Task failed with exception
Traceback (most recent call last):
  File "/home/airflow/.local/lib/python3.9/site-packages/urllib3/connection.py", line 174, in _new_conn
    conn = connection.create_connection(
  File "/home/airflow/.local/lib/python3.9/site-packages/urllib3/util/connection.py", line 72, in create_connection
    for res in socket.getaddrinfo(host, port, family, socket.SOCK_STREAM):
  File "/usr/local/lib/python3.9/socket.py", line 954, in getaddrinfo
    for res in _socket.getaddrinfo(host, port, family, type, proto, flags):
socket.gaierror: [Errno -2] Name or service not known

During handling of the above exception, another exception occurred:

Traceback (most recent call last):
  File "/home/airflow/.local/lib/python3.9/site-packages/urllib3/connectionpool.py", line 703, in urlopen
    httplib_response = self._make_request(
  File "/home/airflow/.local/lib/python3.9/site-packages/urllib3/connectionpool.py", line 386, in _make_request
    self._validate_conn(conn)
  File "/home/airflow/.local/lib/python3.9/site-packages/urllib3/connectionpool.py", line 1042, in _validate_conn
    conn.connect()
  File "/home/airflow/.local/lib/python3.9/site-packages/urllib3/connection.py", line 363, in connect
    self.sock = conn = self._new_conn()
  File "/home/airflow/.local/lib/python3.9/site-packages/urllib3/connection.py", line 186, in _new_conn
    raise NewConnectionError(
urllib3.exceptions.NewConnectionError: <urllib3.connection.HTTPSConnection object at 0x7f57fa98a670>: Failed to establish a new connection: [Errno -2] Name or service not known

During handling of the above exception, another exception occurred:

Traceback (most recent call last):
  File "/home/airflow/.local/lib/python3.9/site-packages/requests/adapters.py", line 487, in send
    resp = conn.urlopen(
  File "/home/airflow/.local/lib/python3.9/site-packages/urllib3/connectionpool.py", line 787, in urlopen
    retries = retries.increment(
  File "/home/airflow/.local/lib/python3.9/site-packages/urllib3/util/retry.py", line 592, in increment
    raise MaxRetryError(_pool, url, error or ResponseError(cause))
urllib3.exceptions.MaxRetryError: HTTPSConnectionPool(host='api.openweathermap.org', port=443): Max retries exceeded with url: /data/3.0/onecall?lat=39.8765&lon=-105.7658&appid=b08c9742b4e2f1bd7b946eaa26c3abab (Caused by NewConnectionError('<urllib3.connection.HTTPSConnection object at 0x7f57fa98a670>: Failed to establish a new connection: [Errno -2] Name or service not known'))

During handling of the above exception, another exception occurred:

Traceback (most recent call last):
  File "/home/airflow/.local/lib/python3.9/site-packages/airflow/operators/python.py", line 181, in execute
    return_value = self.execute_callable()
  File "/home/airflow/.local/lib/python3.9/site-packages/airflow/operators/python.py", line 198, in execute_callable
    return self.python_callable(*self.op_args, **self.op_kwargs)
  File "/opt/airflow/dags/load_weather.py", line 20, in get_resort_weather_response_data
    response = load_data_from_api(lat, lon)
  File "/opt/airflow/dags/load_weather.py", line 31, in load_data_from_api
    response = requests.get(url).json()
  File "/home/airflow/.local/lib/python3.9/site-packages/requests/api.py", line 73, in get
    return request("get", url, params=params, **kwargs)
  File "/home/airflow/.local/lib/python3.9/site-packages/requests/api.py", line 59, in request
    return session.request(method=method, url=url, **kwargs)
  File "/home/airflow/.local/lib/python3.9/site-packages/requests/sessions.py", line 587, in request
    resp = self.send(prep, **send_kwargs)
  File "/home/airflow/.local/lib/python3.9/site-packages/requests/sessions.py", line 701, in send
    r = adapter.send(request, **kwargs)
  File "/home/airflow/.local/lib/python3.9/site-packages/requests/adapters.py", line 520, in send
    raise ConnectionError(e, request=request)
requests.exceptions.ConnectionError: HTTPSConnectionPool(host='api.openweathermap.org', port=443): Max retries exceeded with url: /data/3.0/onecall?lat=39.8765&lon=-105.7658&appid=b08c9742b4e2f1bd7b946eaa26c3abab (Caused by NewConnectionError('<urllib3.connection.HTTPSConnection object at 0x7f57fa98a670>: Failed to establish a new connection: [Errno -2] Name or service not known'))
[2025-02-15T01:50:36.918+0000] {taskinstance.py:1368} INFO - Marking task as FAILED. dag_id=weather_data_ETL, task_id=load_weather, execution_date=20250215T015023, start_date=20250215T015036, end_date=20250215T015036
[2025-02-15T01:50:36.970+0000] {standard_task_runner.py:104} ERROR - Failed to execute job 85 for task load_weather (HTTPSConnectionPool(host='api.openweathermap.org', port=443): Max retries exceeded with url: /data/3.0/onecall?lat=39.8765&lon=-105.7658&appid=b08c9742b4e2f1bd7b946eaa26c3abab (Caused by NewConnectionError('<urllib3.connection.HTTPSConnection object at 0x7f57fa98a670>: Failed to establish a new connection: [Errno -2] Name or service not known')); 49)
[2025-02-15T01:50:36.994+0000] {local_task_job_runner.py:232} INFO - Task exited with return code 1
[2025-02-15T01:50:37.049+0000] {taskinstance.py:2674} INFO - 0 downstream tasks scheduled from follow-on schedule check
