[2025-02-14T21:05:58.020+0000] {taskinstance.py:1125} INFO - Dependencies all met for dep_context=non-requeueable deps ti=<TaskInstance: weather_data_ETL.load_weather manual__2025-02-14T21:05:41.378388+00:00 [queued]>
[2025-02-14T21:05:58.031+0000] {taskinstance.py:1125} INFO - Dependencies all met for dep_context=requeueable deps ti=<TaskInstance: weather_data_ETL.load_weather manual__2025-02-14T21:05:41.378388+00:00 [queued]>
[2025-02-14T21:05:58.031+0000] {taskinstance.py:1331} INFO - Starting attempt 1 of 1
[2025-02-14T21:05:58.047+0000] {taskinstance.py:1350} INFO - Executing <Task(PythonOperator): load_weather> on 2025-02-14 21:05:41.378388+00:00
[2025-02-14T21:05:58.052+0000] {standard_task_runner.py:57} INFO - Started process 68 to run task
[2025-02-14T21:05:58.056+0000] {standard_task_runner.py:84} INFO - Running: ['***', 'tasks', 'run', 'weather_data_ETL', 'load_weather', 'manual__2025-02-14T21:05:41.378388+00:00', '--job-id', '28', '--raw', '--subdir', 'DAGS_FOLDER/weather_data_dag.py', '--cfg-path', '/tmp/tmpwwewgh5r']
[2025-02-14T21:05:58.059+0000] {standard_task_runner.py:85} INFO - Job 28: Subtask load_weather
[2025-02-14T21:05:58.146+0000] {task_command.py:410} INFO - Running <TaskInstance: weather_data_ETL.load_weather manual__2025-02-14T21:05:41.378388+00:00 [running]> on host 527eda61e611
[2025-02-14T21:05:58.303+0000] {taskinstance.py:1568} INFO - Exporting env vars: AIRFLOW_CTX_DAG_OWNER='airscholar' AIRFLOW_CTX_DAG_ID='weather_data_ETL' AIRFLOW_CTX_TASK_ID='load_weather' AIRFLOW_CTX_EXECUTION_DATE='2025-02-14T21:05:41.378388+00:00' AIRFLOW_CTX_TRY_NUMBER='1' AIRFLOW_CTX_DAG_RUN_ID='manual__2025-02-14T21:05:41.378388+00:00'
[2025-02-14T21:05:58.305+0000] {taskinstance.py:1847} ERROR - Task failed with exception
Traceback (most recent call last):
  File "/home/airflow/.local/lib/python3.9/site-packages/airflow/operators/python.py", line 181, in execute
    return_value = self.execute_callable()
  File "/home/airflow/.local/lib/python3.9/site-packages/airflow/operators/python.py", line 198, in execute_callable
    return self.python_callable(*self.op_args, **self.op_kwargs)
  File "/opt/airflow/dags/get_weather.py", line 12, in get_resort_weather_response_data
    for pass_type, resort_name, lat, lon in resorts:
ValueError: not enough values to unpack (expected 4, got 3)
[2025-02-14T21:05:58.325+0000] {taskinstance.py:1368} INFO - Marking task as FAILED. dag_id=weather_data_ETL, task_id=load_weather, execution_date=20250214T210541, start_date=20250214T210558, end_date=20250214T210558
[2025-02-14T21:05:58.346+0000] {standard_task_runner.py:104} ERROR - Failed to execute job 28 for task load_weather (not enough values to unpack (expected 4, got 3); 68)
[2025-02-14T21:05:58.390+0000] {local_task_job_runner.py:232} INFO - Task exited with return code 1
[2025-02-14T21:05:58.428+0000] {taskinstance.py:2674} INFO - 0 downstream tasks scheduled from follow-on schedule check
