[2025-02-11T00:00:18.059+0000] {taskinstance.py:1125} INFO - Dependencies all met for dep_context=non-requeueable deps ti=<TaskInstance: get_current_weather.transform_raw_data scheduled__2025-02-10T00:00:00+00:00 [queued]>
[2025-02-11T00:00:18.073+0000] {taskinstance.py:1125} INFO - Dependencies all met for dep_context=requeueable deps ti=<TaskInstance: get_current_weather.transform_raw_data scheduled__2025-02-10T00:00:00+00:00 [queued]>
[2025-02-11T00:00:18.074+0000] {taskinstance.py:1331} INFO - Starting attempt 1 of 1
[2025-02-11T00:00:18.093+0000] {taskinstance.py:1350} INFO - Executing <Task(PythonOperator): transform_raw_data> on 2025-02-10 00:00:00+00:00
[2025-02-11T00:00:18.101+0000] {standard_task_runner.py:57} INFO - Started process 29533 to run task
[2025-02-11T00:00:18.105+0000] {standard_task_runner.py:84} INFO - Running: ['***', 'tasks', 'run', 'get_current_weather', 'transform_raw_data', 'scheduled__2025-02-10T00:00:00+00:00', '--job-id', '15', '--raw', '--subdir', 'DAGS_FOLDER/weather_data_dag.py', '--cfg-path', '/tmp/tmph39pb6ed']
[2025-02-11T00:00:18.109+0000] {standard_task_runner.py:85} INFO - Job 15: Subtask transform_raw_data
[2025-02-11T00:00:18.238+0000] {task_command.py:410} INFO - Running <TaskInstance: get_current_weather.transform_raw_data scheduled__2025-02-10T00:00:00+00:00 [running]> on host 5a15db971c3c
[2025-02-11T00:00:18.437+0000] {taskinstance.py:1568} INFO - Exporting env vars: AIRFLOW_CTX_DAG_OWNER='airscholar' AIRFLOW_CTX_DAG_ID='get_current_weather' AIRFLOW_CTX_TASK_ID='transform_raw_data' AIRFLOW_CTX_EXECUTION_DATE='2025-02-10T00:00:00+00:00' AIRFLOW_CTX_TRY_NUMBER='1' AIRFLOW_CTX_DAG_RUN_ID='scheduled__2025-02-10T00:00:00+00:00'
[2025-02-11T00:00:18.494+0000] {taskinstance.py:1847} ERROR - Task failed with exception
Traceback (most recent call last):
  File "/home/airflow/.local/lib/python3.9/site-packages/pandas/core/indexes/base.py", line 3802, in get_loc
    return self._engine.get_loc(casted_key)
  File "pandas/_libs/index.pyx", line 138, in pandas._libs.index.IndexEngine.get_loc
  File "pandas/_libs/index.pyx", line 165, in pandas._libs.index.IndexEngine.get_loc
  File "pandas/_libs/hashtable_class_helper.pxi", line 5745, in pandas._libs.hashtable.PyObjectHashTable.get_item
  File "pandas/_libs/hashtable_class_helper.pxi", line 5753, in pandas._libs.hashtable.PyObjectHashTable.get_item
KeyError: ''

The above exception was the direct cause of the following exception:

Traceback (most recent call last):
  File "/home/airflow/.local/lib/python3.9/site-packages/airflow/operators/python.py", line 181, in execute
    return_value = self.execute_callable()
  File "/home/airflow/.local/lib/python3.9/site-packages/airflow/operators/python.py", line 198, in execute_callable
    return self.python_callable(*self.op_args, **self.op_kwargs)
  File "/opt/airflow/dags/get_current_weather.py", line 139, in transform
    df['']
  File "/home/airflow/.local/lib/python3.9/site-packages/pandas/core/frame.py", line 3807, in __getitem__
    indexer = self.columns.get_loc(key)
  File "/home/airflow/.local/lib/python3.9/site-packages/pandas/core/indexes/base.py", line 3804, in get_loc
    raise KeyError(key) from err
KeyError: ''
[2025-02-11T00:00:18.531+0000] {taskinstance.py:1368} INFO - Marking task as FAILED. dag_id=get_current_weather, task_id=transform_raw_data, execution_date=20250210T000000, start_date=20250211T000018, end_date=20250211T000018
[2025-02-11T00:00:18.563+0000] {standard_task_runner.py:104} ERROR - Failed to execute job 15 for task transform_raw_data (''; 29533)
[2025-02-11T00:00:18.603+0000] {local_task_job_runner.py:232} INFO - Task exited with return code 1
[2025-02-11T00:00:18.651+0000] {taskinstance.py:2674} INFO - 0 downstream tasks scheduled from follow-on schedule check
