[2025-02-04T02:27:51.438+0000] {processor.py:156} INFO - Started process (PID=22) to work on /opt/airflow/dags/weather_data_dag.py
[2025-02-04T02:27:51.439+0000] {processor.py:799} INFO - Processing file /opt/airflow/dags/weather_data_dag.py for tasks to queue
[2025-02-04T02:27:51.441+0000] {logging_mixin.py:149} INFO - [2025-02-04T02:27:51.441+0000] {dagbag.py:541} INFO - Filling up the DagBag from /opt/airflow/dags/weather_data_dag.py
[2025-02-04T02:27:51.460+0000] {logging_mixin.py:149} INFO - [2025-02-04T02:27:51.458+0000] {dagbag.py:350} ERROR - Failed to import: /opt/airflow/dags/weather_data_dag.py
Traceback (most recent call last):
  File "/home/airflow/.local/lib/python3.9/site-packages/airflow/models/dagbag.py", line 346, in parse
    loader.exec_module(new_module)
  File "<frozen importlib._bootstrap_external>", line 850, in exec_module
  File "<frozen importlib._bootstrap>", line 228, in _call_with_frames_removed
  File "/opt/airflow/dags/weather_data_dag.py", line 23, in <module>
    python_callable=create_topic_in_kafka
NameError: name 'create_topic_in_kafka' is not defined
[2025-02-04T02:27:51.462+0000] {processor.py:811} WARNING - No viable dags retrieved from /opt/airflow/dags/weather_data_dag.py
[2025-02-04T02:27:51.479+0000] {processor.py:178} INFO - Processing /opt/airflow/dags/weather_data_dag.py took 0.045 seconds
[2025-02-04T02:28:21.706+0000] {processor.py:156} INFO - Started process (PID=23) to work on /opt/airflow/dags/weather_data_dag.py
[2025-02-04T02:28:21.708+0000] {processor.py:799} INFO - Processing file /opt/airflow/dags/weather_data_dag.py for tasks to queue
[2025-02-04T02:28:21.710+0000] {logging_mixin.py:149} INFO - [2025-02-04T02:28:21.710+0000] {dagbag.py:541} INFO - Filling up the DagBag from /opt/airflow/dags/weather_data_dag.py
[2025-02-04T02:28:21.723+0000] {logging_mixin.py:149} INFO - [2025-02-04T02:28:21.721+0000] {dagbag.py:350} ERROR - Failed to import: /opt/airflow/dags/weather_data_dag.py
Traceback (most recent call last):
  File "/home/airflow/.local/lib/python3.9/site-packages/airflow/models/dagbag.py", line 346, in parse
    loader.exec_module(new_module)
  File "<frozen importlib._bootstrap_external>", line 850, in exec_module
  File "<frozen importlib._bootstrap>", line 228, in _call_with_frames_removed
  File "/opt/airflow/dags/weather_data_dag.py", line 23, in <module>
    python_callable=create_topic_in_kafka
NameError: name 'create_topic_in_kafka' is not defined
[2025-02-04T02:28:21.724+0000] {processor.py:811} WARNING - No viable dags retrieved from /opt/airflow/dags/weather_data_dag.py
[2025-02-04T02:28:21.751+0000] {processor.py:178} INFO - Processing /opt/airflow/dags/weather_data_dag.py took 0.048 seconds
[2025-02-04T02:28:52.241+0000] {processor.py:156} INFO - Started process (PID=24) to work on /opt/airflow/dags/weather_data_dag.py
[2025-02-04T02:28:52.243+0000] {processor.py:799} INFO - Processing file /opt/airflow/dags/weather_data_dag.py for tasks to queue
[2025-02-04T02:28:52.245+0000] {logging_mixin.py:149} INFO - [2025-02-04T02:28:52.244+0000] {dagbag.py:541} INFO - Filling up the DagBag from /opt/airflow/dags/weather_data_dag.py
[2025-02-04T02:28:52.272+0000] {logging_mixin.py:149} INFO - [2025-02-04T02:28:52.269+0000] {dagbag.py:350} ERROR - Failed to import: /opt/airflow/dags/weather_data_dag.py
Traceback (most recent call last):
  File "/home/airflow/.local/lib/python3.9/site-packages/airflow/models/dagbag.py", line 346, in parse
    loader.exec_module(new_module)
  File "<frozen importlib._bootstrap_external>", line 850, in exec_module
  File "<frozen importlib._bootstrap>", line 228, in _call_with_frames_removed
  File "/opt/airflow/dags/weather_data_dag.py", line 23, in <module>
    python_callable=create_topic_in_kafka
NameError: name 'create_topic_in_kafka' is not defined
[2025-02-04T02:28:52.273+0000] {processor.py:811} WARNING - No viable dags retrieved from /opt/airflow/dags/weather_data_dag.py
[2025-02-04T02:28:52.292+0000] {processor.py:178} INFO - Processing /opt/airflow/dags/weather_data_dag.py took 0.055 seconds
[2025-02-04T02:31:34.359+0000] {processor.py:156} INFO - Started process (PID=22) to work on /opt/airflow/dags/weather_data_dag.py
[2025-02-04T02:31:34.362+0000] {processor.py:799} INFO - Processing file /opt/airflow/dags/weather_data_dag.py for tasks to queue
[2025-02-04T02:31:34.363+0000] {logging_mixin.py:149} INFO - [2025-02-04T02:31:34.363+0000] {dagbag.py:541} INFO - Filling up the DagBag from /opt/airflow/dags/weather_data_dag.py
[2025-02-04T02:31:34.375+0000] {logging_mixin.py:149} INFO - [2025-02-04T02:31:34.372+0000] {dagbag.py:350} ERROR - Failed to import: /opt/airflow/dags/weather_data_dag.py
Traceback (most recent call last):
  File "/home/airflow/.local/lib/python3.9/site-packages/airflow/models/dagbag.py", line 346, in parse
    loader.exec_module(new_module)
  File "<frozen importlib._bootstrap_external>", line 850, in exec_module
  File "<frozen importlib._bootstrap>", line 228, in _call_with_frames_removed
  File "/opt/airflow/dags/weather_data_dag.py", line 23, in <module>
    python_callable=create_topic_in_kafka
NameError: name 'create_topic_in_kafka' is not defined
[2025-02-04T02:31:34.376+0000] {processor.py:811} WARNING - No viable dags retrieved from /opt/airflow/dags/weather_data_dag.py
[2025-02-04T02:31:34.393+0000] {processor.py:178} INFO - Processing /opt/airflow/dags/weather_data_dag.py took 0.038 seconds
[2025-02-04T02:32:04.599+0000] {processor.py:156} INFO - Started process (PID=23) to work on /opt/airflow/dags/weather_data_dag.py
[2025-02-04T02:32:04.601+0000] {processor.py:799} INFO - Processing file /opt/airflow/dags/weather_data_dag.py for tasks to queue
[2025-02-04T02:32:04.603+0000] {logging_mixin.py:149} INFO - [2025-02-04T02:32:04.603+0000] {dagbag.py:541} INFO - Filling up the DagBag from /opt/airflow/dags/weather_data_dag.py
[2025-02-04T02:32:04.616+0000] {logging_mixin.py:149} INFO - [2025-02-04T02:32:04.614+0000] {dagbag.py:350} ERROR - Failed to import: /opt/airflow/dags/weather_data_dag.py
Traceback (most recent call last):
  File "/home/airflow/.local/lib/python3.9/site-packages/airflow/models/dagbag.py", line 346, in parse
    loader.exec_module(new_module)
  File "<frozen importlib._bootstrap_external>", line 850, in exec_module
  File "<frozen importlib._bootstrap>", line 228, in _call_with_frames_removed
  File "/opt/airflow/dags/weather_data_dag.py", line 23, in <module>
    python_callable=create_topic_in_kafka
NameError: name 'create_topic_in_kafka' is not defined
[2025-02-04T02:32:04.618+0000] {processor.py:811} WARNING - No viable dags retrieved from /opt/airflow/dags/weather_data_dag.py
[2025-02-04T02:32:04.647+0000] {processor.py:178} INFO - Processing /opt/airflow/dags/weather_data_dag.py took 0.052 seconds
[2025-02-04T02:32:57.551+0000] {processor.py:156} INFO - Started process (PID=23) to work on /opt/airflow/dags/weather_data_dag.py
[2025-02-04T02:32:57.553+0000] {processor.py:799} INFO - Processing file /opt/airflow/dags/weather_data_dag.py for tasks to queue
[2025-02-04T02:32:57.554+0000] {logging_mixin.py:149} INFO - [2025-02-04T02:32:57.554+0000] {dagbag.py:541} INFO - Filling up the DagBag from /opt/airflow/dags/weather_data_dag.py
[2025-02-04T02:32:57.566+0000] {logging_mixin.py:149} INFO - [2025-02-04T02:32:57.564+0000] {dagbag.py:350} ERROR - Failed to import: /opt/airflow/dags/weather_data_dag.py
Traceback (most recent call last):
  File "/home/airflow/.local/lib/python3.9/site-packages/airflow/models/dagbag.py", line 346, in parse
    loader.exec_module(new_module)
  File "<frozen importlib._bootstrap_external>", line 850, in exec_module
  File "<frozen importlib._bootstrap>", line 228, in _call_with_frames_removed
  File "/opt/airflow/dags/weather_data_dag.py", line 23, in <module>
    python_callable=create_topic_in_kafka
NameError: name 'create_topic_in_kafka' is not defined
[2025-02-04T02:32:57.567+0000] {processor.py:811} WARNING - No viable dags retrieved from /opt/airflow/dags/weather_data_dag.py
[2025-02-04T02:32:57.586+0000] {processor.py:178} INFO - Processing /opt/airflow/dags/weather_data_dag.py took 0.038 seconds
[2025-02-04T02:33:27.775+0000] {processor.py:156} INFO - Started process (PID=24) to work on /opt/airflow/dags/weather_data_dag.py
[2025-02-04T02:33:27.778+0000] {processor.py:799} INFO - Processing file /opt/airflow/dags/weather_data_dag.py for tasks to queue
[2025-02-04T02:33:27.780+0000] {logging_mixin.py:149} INFO - [2025-02-04T02:33:27.780+0000] {dagbag.py:541} INFO - Filling up the DagBag from /opt/airflow/dags/weather_data_dag.py
[2025-02-04T02:33:27.796+0000] {logging_mixin.py:149} INFO - [2025-02-04T02:33:27.792+0000] {dagbag.py:350} ERROR - Failed to import: /opt/airflow/dags/weather_data_dag.py
Traceback (most recent call last):
  File "/home/airflow/.local/lib/python3.9/site-packages/airflow/models/dagbag.py", line 346, in parse
    loader.exec_module(new_module)
  File "<frozen importlib._bootstrap_external>", line 850, in exec_module
  File "<frozen importlib._bootstrap>", line 228, in _call_with_frames_removed
  File "/opt/airflow/dags/weather_data_dag.py", line 23, in <module>
    python_callable=create_topic_in_kafka
NameError: name 'create_topic_in_kafka' is not defined
[2025-02-04T02:33:27.797+0000] {processor.py:811} WARNING - No viable dags retrieved from /opt/airflow/dags/weather_data_dag.py
[2025-02-04T02:33:27.819+0000] {processor.py:178} INFO - Processing /opt/airflow/dags/weather_data_dag.py took 0.048 seconds
[2025-02-04T02:33:58.279+0000] {processor.py:156} INFO - Started process (PID=25) to work on /opt/airflow/dags/weather_data_dag.py
[2025-02-04T02:33:58.281+0000] {processor.py:799} INFO - Processing file /opt/airflow/dags/weather_data_dag.py for tasks to queue
[2025-02-04T02:33:58.282+0000] {logging_mixin.py:149} INFO - [2025-02-04T02:33:58.282+0000] {dagbag.py:541} INFO - Filling up the DagBag from /opt/airflow/dags/weather_data_dag.py
[2025-02-04T02:33:58.296+0000] {logging_mixin.py:149} INFO - [2025-02-04T02:33:58.294+0000] {dagbag.py:350} ERROR - Failed to import: /opt/airflow/dags/weather_data_dag.py
Traceback (most recent call last):
  File "/home/airflow/.local/lib/python3.9/site-packages/airflow/models/dagbag.py", line 346, in parse
    loader.exec_module(new_module)
  File "<frozen importlib._bootstrap_external>", line 850, in exec_module
  File "<frozen importlib._bootstrap>", line 228, in _call_with_frames_removed
  File "/opt/airflow/dags/weather_data_dag.py", line 23, in <module>
    python_callable=create_topic_in_kafka
NameError: name 'create_topic_in_kafka' is not defined
[2025-02-04T02:33:58.297+0000] {processor.py:811} WARNING - No viable dags retrieved from /opt/airflow/dags/weather_data_dag.py
[2025-02-04T02:33:58.317+0000] {processor.py:178} INFO - Processing /opt/airflow/dags/weather_data_dag.py took 0.042 seconds
[2025-02-04T02:34:55.071+0000] {processor.py:156} INFO - Started process (PID=22) to work on /opt/airflow/dags/weather_data_dag.py
[2025-02-04T02:34:55.074+0000] {processor.py:799} INFO - Processing file /opt/airflow/dags/weather_data_dag.py for tasks to queue
[2025-02-04T02:34:55.075+0000] {logging_mixin.py:149} INFO - [2025-02-04T02:34:55.075+0000] {dagbag.py:541} INFO - Filling up the DagBag from /opt/airflow/dags/weather_data_dag.py
[2025-02-04T02:34:55.088+0000] {logging_mixin.py:149} INFO - [2025-02-04T02:34:55.086+0000] {dagbag.py:350} ERROR - Failed to import: /opt/airflow/dags/weather_data_dag.py
Traceback (most recent call last):
  File "/home/airflow/.local/lib/python3.9/site-packages/airflow/models/dagbag.py", line 346, in parse
    loader.exec_module(new_module)
  File "<frozen importlib._bootstrap_external>", line 850, in exec_module
  File "<frozen importlib._bootstrap>", line 228, in _call_with_frames_removed
  File "/opt/airflow/dags/weather_data_dag.py", line 23, in <module>
    python_callable=create_topic_in_kafka
NameError: name 'create_topic_in_kafka' is not defined
[2025-02-04T02:34:55.089+0000] {processor.py:811} WARNING - No viable dags retrieved from /opt/airflow/dags/weather_data_dag.py
[2025-02-04T02:34:55.108+0000] {processor.py:178} INFO - Processing /opt/airflow/dags/weather_data_dag.py took 0.040 seconds
[2025-02-04T02:35:25.185+0000] {processor.py:156} INFO - Started process (PID=23) to work on /opt/airflow/dags/weather_data_dag.py
[2025-02-04T02:35:25.188+0000] {processor.py:799} INFO - Processing file /opt/airflow/dags/weather_data_dag.py for tasks to queue
[2025-02-04T02:35:25.190+0000] {logging_mixin.py:149} INFO - [2025-02-04T02:35:25.190+0000] {dagbag.py:541} INFO - Filling up the DagBag from /opt/airflow/dags/weather_data_dag.py
[2025-02-04T02:35:25.204+0000] {logging_mixin.py:149} INFO - [2025-02-04T02:35:25.202+0000] {dagbag.py:350} ERROR - Failed to import: /opt/airflow/dags/weather_data_dag.py
Traceback (most recent call last):
  File "/home/airflow/.local/lib/python3.9/site-packages/airflow/models/dagbag.py", line 346, in parse
    loader.exec_module(new_module)
  File "<frozen importlib._bootstrap_external>", line 850, in exec_module
  File "<frozen importlib._bootstrap>", line 228, in _call_with_frames_removed
  File "/opt/airflow/dags/weather_data_dag.py", line 23, in <module>
    python_callable=create_topic_in_kafka
NameError: name 'create_topic_in_kafka' is not defined
[2025-02-04T02:35:25.205+0000] {processor.py:811} WARNING - No viable dags retrieved from /opt/airflow/dags/weather_data_dag.py
[2025-02-04T02:35:25.241+0000] {processor.py:178} INFO - Processing /opt/airflow/dags/weather_data_dag.py took 0.060 seconds
[2025-02-04T02:37:43.723+0000] {processor.py:156} INFO - Started process (PID=23) to work on /opt/airflow/dags/weather_data_dag.py
[2025-02-04T02:37:43.726+0000] {processor.py:799} INFO - Processing file /opt/airflow/dags/weather_data_dag.py for tasks to queue
[2025-02-04T02:37:43.727+0000] {logging_mixin.py:149} INFO - [2025-02-04T02:37:43.727+0000] {dagbag.py:541} INFO - Filling up the DagBag from /opt/airflow/dags/weather_data_dag.py
[2025-02-04T02:37:43.745+0000] {logging_mixin.py:149} INFO - [2025-02-04T02:37:43.742+0000] {dagbag.py:350} ERROR - Failed to import: /opt/airflow/dags/weather_data_dag.py
Traceback (most recent call last):
  File "/home/airflow/.local/lib/python3.9/site-packages/airflow/models/dagbag.py", line 346, in parse
    loader.exec_module(new_module)
  File "<frozen importlib._bootstrap_external>", line 850, in exec_module
  File "<frozen importlib._bootstrap>", line 228, in _call_with_frames_removed
  File "/opt/airflow/dags/weather_data_dag.py", line 23, in <module>
    python_callable=create_topic_in_kafka
NameError: name 'create_topic_in_kafka' is not defined
[2025-02-04T02:37:43.747+0000] {processor.py:811} WARNING - No viable dags retrieved from /opt/airflow/dags/weather_data_dag.py
[2025-02-04T02:37:43.794+0000] {processor.py:178} INFO - Processing /opt/airflow/dags/weather_data_dag.py took 0.080 seconds
[2025-02-04T02:38:14.902+0000] {processor.py:156} INFO - Started process (PID=24) to work on /opt/airflow/dags/weather_data_dag.py
[2025-02-04T02:38:14.906+0000] {processor.py:799} INFO - Processing file /opt/airflow/dags/weather_data_dag.py for tasks to queue
[2025-02-04T02:38:14.908+0000] {logging_mixin.py:149} INFO - [2025-02-04T02:38:14.908+0000] {dagbag.py:541} INFO - Filling up the DagBag from /opt/airflow/dags/weather_data_dag.py
[2025-02-04T02:38:14.936+0000] {logging_mixin.py:149} INFO - [2025-02-04T02:38:14.931+0000] {dagbag.py:350} ERROR - Failed to import: /opt/airflow/dags/weather_data_dag.py
Traceback (most recent call last):
  File "/home/airflow/.local/lib/python3.9/site-packages/airflow/models/dagbag.py", line 346, in parse
    loader.exec_module(new_module)
  File "<frozen importlib._bootstrap_external>", line 850, in exec_module
  File "<frozen importlib._bootstrap>", line 228, in _call_with_frames_removed
  File "/opt/airflow/dags/weather_data_dag.py", line 23, in <module>
    python_callable=create_topic_in_kafka
NameError: name 'create_topic_in_kafka' is not defined
[2025-02-04T02:38:14.938+0000] {processor.py:811} WARNING - No viable dags retrieved from /opt/airflow/dags/weather_data_dag.py
[2025-02-04T02:38:14.981+0000] {processor.py:178} INFO - Processing /opt/airflow/dags/weather_data_dag.py took 0.090 seconds
[2025-02-04T02:38:45.270+0000] {processor.py:156} INFO - Started process (PID=25) to work on /opt/airflow/dags/weather_data_dag.py
[2025-02-04T02:38:45.276+0000] {processor.py:799} INFO - Processing file /opt/airflow/dags/weather_data_dag.py for tasks to queue
[2025-02-04T02:38:45.279+0000] {logging_mixin.py:149} INFO - [2025-02-04T02:38:45.279+0000] {dagbag.py:541} INFO - Filling up the DagBag from /opt/airflow/dags/weather_data_dag.py
[2025-02-04T02:38:45.316+0000] {logging_mixin.py:149} INFO - [2025-02-04T02:38:45.310+0000] {dagbag.py:350} ERROR - Failed to import: /opt/airflow/dags/weather_data_dag.py
Traceback (most recent call last):
  File "/home/airflow/.local/lib/python3.9/site-packages/airflow/models/dagbag.py", line 346, in parse
    loader.exec_module(new_module)
  File "<frozen importlib._bootstrap_external>", line 850, in exec_module
  File "<frozen importlib._bootstrap>", line 228, in _call_with_frames_removed
  File "/opt/airflow/dags/weather_data_dag.py", line 23, in <module>
    python_callable=create_topic_in_kafka
NameError: name 'create_topic_in_kafka' is not defined
[2025-02-04T02:38:45.318+0000] {processor.py:811} WARNING - No viable dags retrieved from /opt/airflow/dags/weather_data_dag.py
[2025-02-04T02:38:45.368+0000] {processor.py:178} INFO - Processing /opt/airflow/dags/weather_data_dag.py took 0.110 seconds
[2025-02-04T02:39:15.506+0000] {processor.py:156} INFO - Started process (PID=26) to work on /opt/airflow/dags/weather_data_dag.py
[2025-02-04T02:39:15.508+0000] {processor.py:799} INFO - Processing file /opt/airflow/dags/weather_data_dag.py for tasks to queue
[2025-02-04T02:39:15.510+0000] {logging_mixin.py:149} INFO - [2025-02-04T02:39:15.509+0000] {dagbag.py:541} INFO - Filling up the DagBag from /opt/airflow/dags/weather_data_dag.py
[2025-02-04T02:39:15.524+0000] {logging_mixin.py:149} INFO - [2025-02-04T02:39:15.521+0000] {dagbag.py:350} ERROR - Failed to import: /opt/airflow/dags/weather_data_dag.py
Traceback (most recent call last):
  File "/home/airflow/.local/lib/python3.9/site-packages/airflow/models/dagbag.py", line 346, in parse
    loader.exec_module(new_module)
  File "<frozen importlib._bootstrap_external>", line 850, in exec_module
  File "<frozen importlib._bootstrap>", line 228, in _call_with_frames_removed
  File "/opt/airflow/dags/weather_data_dag.py", line 23, in <module>
    python_callable=create_topic_in_kafka
NameError: name 'create_topic_in_kafka' is not defined
[2025-02-04T02:39:15.526+0000] {processor.py:811} WARNING - No viable dags retrieved from /opt/airflow/dags/weather_data_dag.py
[2025-02-04T02:39:15.561+0000] {processor.py:178} INFO - Processing /opt/airflow/dags/weather_data_dag.py took 0.060 seconds
[2025-02-04T02:39:45.807+0000] {processor.py:156} INFO - Started process (PID=27) to work on /opt/airflow/dags/weather_data_dag.py
[2025-02-04T02:39:45.810+0000] {processor.py:799} INFO - Processing file /opt/airflow/dags/weather_data_dag.py for tasks to queue
[2025-02-04T02:39:45.813+0000] {logging_mixin.py:149} INFO - [2025-02-04T02:39:45.813+0000] {dagbag.py:541} INFO - Filling up the DagBag from /opt/airflow/dags/weather_data_dag.py
[2025-02-04T02:39:45.834+0000] {logging_mixin.py:149} INFO - [2025-02-04T02:39:45.831+0000] {dagbag.py:350} ERROR - Failed to import: /opt/airflow/dags/weather_data_dag.py
Traceback (most recent call last):
  File "/home/airflow/.local/lib/python3.9/site-packages/airflow/models/dagbag.py", line 346, in parse
    loader.exec_module(new_module)
  File "<frozen importlib._bootstrap_external>", line 850, in exec_module
  File "<frozen importlib._bootstrap>", line 228, in _call_with_frames_removed
  File "/opt/airflow/dags/weather_data_dag.py", line 23, in <module>
    python_callable=create_topic_in_kafka
NameError: name 'create_topic_in_kafka' is not defined
[2025-02-04T02:39:45.835+0000] {processor.py:811} WARNING - No viable dags retrieved from /opt/airflow/dags/weather_data_dag.py
[2025-02-04T02:39:45.858+0000] {processor.py:178} INFO - Processing /opt/airflow/dags/weather_data_dag.py took 0.055 seconds
[2025-02-04T02:40:16.095+0000] {processor.py:156} INFO - Started process (PID=28) to work on /opt/airflow/dags/weather_data_dag.py
[2025-02-04T02:40:16.098+0000] {processor.py:799} INFO - Processing file /opt/airflow/dags/weather_data_dag.py for tasks to queue
[2025-02-04T02:40:16.100+0000] {logging_mixin.py:149} INFO - [2025-02-04T02:40:16.099+0000] {dagbag.py:541} INFO - Filling up the DagBag from /opt/airflow/dags/weather_data_dag.py
[2025-02-04T02:40:16.113+0000] {logging_mixin.py:149} INFO - [2025-02-04T02:40:16.111+0000] {dagbag.py:350} ERROR - Failed to import: /opt/airflow/dags/weather_data_dag.py
Traceback (most recent call last):
  File "/home/airflow/.local/lib/python3.9/site-packages/airflow/models/dagbag.py", line 346, in parse
    loader.exec_module(new_module)
  File "<frozen importlib._bootstrap_external>", line 850, in exec_module
  File "<frozen importlib._bootstrap>", line 228, in _call_with_frames_removed
  File "/opt/airflow/dags/weather_data_dag.py", line 23, in <module>
    python_callable=create_topic_in_kafka
NameError: name 'create_topic_in_kafka' is not defined
[2025-02-04T02:40:16.114+0000] {processor.py:811} WARNING - No viable dags retrieved from /opt/airflow/dags/weather_data_dag.py
[2025-02-04T02:40:16.135+0000] {processor.py:178} INFO - Processing /opt/airflow/dags/weather_data_dag.py took 0.044 seconds
[2025-02-04T02:40:46.686+0000] {processor.py:156} INFO - Started process (PID=29) to work on /opt/airflow/dags/weather_data_dag.py
[2025-02-04T02:40:46.689+0000] {processor.py:799} INFO - Processing file /opt/airflow/dags/weather_data_dag.py for tasks to queue
[2025-02-04T02:40:46.691+0000] {logging_mixin.py:149} INFO - [2025-02-04T02:40:46.690+0000] {dagbag.py:541} INFO - Filling up the DagBag from /opt/airflow/dags/weather_data_dag.py
[2025-02-04T02:40:46.713+0000] {logging_mixin.py:149} INFO - [2025-02-04T02:40:46.710+0000] {dagbag.py:350} ERROR - Failed to import: /opt/airflow/dags/weather_data_dag.py
Traceback (most recent call last):
  File "/home/airflow/.local/lib/python3.9/site-packages/airflow/models/dagbag.py", line 346, in parse
    loader.exec_module(new_module)
  File "<frozen importlib._bootstrap_external>", line 850, in exec_module
  File "<frozen importlib._bootstrap>", line 228, in _call_with_frames_removed
  File "/opt/airflow/dags/weather_data_dag.py", line 23, in <module>
    python_callable=create_topic_in_kafka
NameError: name 'create_topic_in_kafka' is not defined
[2025-02-04T02:40:46.716+0000] {processor.py:811} WARNING - No viable dags retrieved from /opt/airflow/dags/weather_data_dag.py
[2025-02-04T02:40:46.740+0000] {processor.py:178} INFO - Processing /opt/airflow/dags/weather_data_dag.py took 0.060 seconds
[2025-02-04T02:41:17.057+0000] {processor.py:156} INFO - Started process (PID=30) to work on /opt/airflow/dags/weather_data_dag.py
[2025-02-04T02:41:17.059+0000] {processor.py:799} INFO - Processing file /opt/airflow/dags/weather_data_dag.py for tasks to queue
[2025-02-04T02:41:17.060+0000] {logging_mixin.py:149} INFO - [2025-02-04T02:41:17.060+0000] {dagbag.py:541} INFO - Filling up the DagBag from /opt/airflow/dags/weather_data_dag.py
[2025-02-04T02:41:17.074+0000] {logging_mixin.py:149} INFO - [2025-02-04T02:41:17.072+0000] {dagbag.py:350} ERROR - Failed to import: /opt/airflow/dags/weather_data_dag.py
Traceback (most recent call last):
  File "/home/airflow/.local/lib/python3.9/site-packages/airflow/models/dagbag.py", line 346, in parse
    loader.exec_module(new_module)
  File "<frozen importlib._bootstrap_external>", line 850, in exec_module
  File "<frozen importlib._bootstrap>", line 228, in _call_with_frames_removed
  File "/opt/airflow/dags/weather_data_dag.py", line 23, in <module>
    python_callable=create_topic_in_kafka
NameError: name 'create_topic_in_kafka' is not defined
[2025-02-04T02:41:17.076+0000] {processor.py:811} WARNING - No viable dags retrieved from /opt/airflow/dags/weather_data_dag.py
[2025-02-04T02:41:17.095+0000] {processor.py:178} INFO - Processing /opt/airflow/dags/weather_data_dag.py took 0.042 seconds
[2025-02-04T02:41:47.417+0000] {processor.py:156} INFO - Started process (PID=31) to work on /opt/airflow/dags/weather_data_dag.py
[2025-02-04T02:41:47.419+0000] {processor.py:799} INFO - Processing file /opt/airflow/dags/weather_data_dag.py for tasks to queue
[2025-02-04T02:41:47.421+0000] {logging_mixin.py:149} INFO - [2025-02-04T02:41:47.421+0000] {dagbag.py:541} INFO - Filling up the DagBag from /opt/airflow/dags/weather_data_dag.py
[2025-02-04T02:41:47.436+0000] {logging_mixin.py:149} INFO - [2025-02-04T02:41:47.433+0000] {dagbag.py:350} ERROR - Failed to import: /opt/airflow/dags/weather_data_dag.py
Traceback (most recent call last):
  File "/home/airflow/.local/lib/python3.9/site-packages/airflow/models/dagbag.py", line 346, in parse
    loader.exec_module(new_module)
  File "<frozen importlib._bootstrap_external>", line 850, in exec_module
  File "<frozen importlib._bootstrap>", line 228, in _call_with_frames_removed
  File "/opt/airflow/dags/weather_data_dag.py", line 23, in <module>
    python_callable=create_topic_in_kafka
NameError: name 'create_topic_in_kafka' is not defined
[2025-02-04T02:41:47.437+0000] {processor.py:811} WARNING - No viable dags retrieved from /opt/airflow/dags/weather_data_dag.py
[2025-02-04T02:41:47.459+0000] {processor.py:178} INFO - Processing /opt/airflow/dags/weather_data_dag.py took 0.046 seconds
[2025-02-04T02:42:17.699+0000] {processor.py:156} INFO - Started process (PID=32) to work on /opt/airflow/dags/weather_data_dag.py
[2025-02-04T02:42:17.704+0000] {processor.py:799} INFO - Processing file /opt/airflow/dags/weather_data_dag.py for tasks to queue
[2025-02-04T02:42:17.707+0000] {logging_mixin.py:149} INFO - [2025-02-04T02:42:17.706+0000] {dagbag.py:541} INFO - Filling up the DagBag from /opt/airflow/dags/weather_data_dag.py
[2025-02-04T02:42:17.722+0000] {logging_mixin.py:149} INFO - [2025-02-04T02:42:17.719+0000] {dagbag.py:350} ERROR - Failed to import: /opt/airflow/dags/weather_data_dag.py
Traceback (most recent call last):
  File "/home/airflow/.local/lib/python3.9/site-packages/airflow/models/dagbag.py", line 346, in parse
    loader.exec_module(new_module)
  File "<frozen importlib._bootstrap_external>", line 850, in exec_module
  File "<frozen importlib._bootstrap>", line 228, in _call_with_frames_removed
  File "/opt/airflow/dags/weather_data_dag.py", line 23, in <module>
    python_callable=create_topic_in_kafka
NameError: name 'create_topic_in_kafka' is not defined
[2025-02-04T02:42:17.724+0000] {processor.py:811} WARNING - No viable dags retrieved from /opt/airflow/dags/weather_data_dag.py
[2025-02-04T02:42:17.759+0000] {processor.py:178} INFO - Processing /opt/airflow/dags/weather_data_dag.py took 0.064 seconds
[2025-02-04T02:42:48.130+0000] {processor.py:156} INFO - Started process (PID=33) to work on /opt/airflow/dags/weather_data_dag.py
[2025-02-04T02:42:48.132+0000] {processor.py:799} INFO - Processing file /opt/airflow/dags/weather_data_dag.py for tasks to queue
[2025-02-04T02:42:48.134+0000] {logging_mixin.py:149} INFO - [2025-02-04T02:42:48.133+0000] {dagbag.py:541} INFO - Filling up the DagBag from /opt/airflow/dags/weather_data_dag.py
[2025-02-04T02:42:48.152+0000] {logging_mixin.py:149} INFO - [2025-02-04T02:42:48.150+0000] {dagbag.py:350} ERROR - Failed to import: /opt/airflow/dags/weather_data_dag.py
Traceback (most recent call last):
  File "/home/airflow/.local/lib/python3.9/site-packages/airflow/models/dagbag.py", line 346, in parse
    loader.exec_module(new_module)
  File "<frozen importlib._bootstrap_external>", line 850, in exec_module
  File "<frozen importlib._bootstrap>", line 228, in _call_with_frames_removed
  File "/opt/airflow/dags/weather_data_dag.py", line 23, in <module>
    python_callable=create_topic_in_kafka
NameError: name 'create_topic_in_kafka' is not defined
[2025-02-04T02:42:48.153+0000] {processor.py:811} WARNING - No viable dags retrieved from /opt/airflow/dags/weather_data_dag.py
[2025-02-04T02:42:48.190+0000] {processor.py:178} INFO - Processing /opt/airflow/dags/weather_data_dag.py took 0.064 seconds
[2025-02-04T02:43:18.304+0000] {processor.py:156} INFO - Started process (PID=34) to work on /opt/airflow/dags/weather_data_dag.py
[2025-02-04T02:43:18.307+0000] {processor.py:799} INFO - Processing file /opt/airflow/dags/weather_data_dag.py for tasks to queue
[2025-02-04T02:43:18.308+0000] {logging_mixin.py:149} INFO - [2025-02-04T02:43:18.308+0000] {dagbag.py:541} INFO - Filling up the DagBag from /opt/airflow/dags/weather_data_dag.py
[2025-02-04T02:43:18.322+0000] {logging_mixin.py:149} INFO - [2025-02-04T02:43:18.319+0000] {dagbag.py:350} ERROR - Failed to import: /opt/airflow/dags/weather_data_dag.py
Traceback (most recent call last):
  File "/home/airflow/.local/lib/python3.9/site-packages/airflow/models/dagbag.py", line 346, in parse
    loader.exec_module(new_module)
  File "<frozen importlib._bootstrap_external>", line 850, in exec_module
  File "<frozen importlib._bootstrap>", line 228, in _call_with_frames_removed
  File "/opt/airflow/dags/weather_data_dag.py", line 23, in <module>
    python_callable=create_topic_in_kafka
NameError: name 'create_topic_in_kafka' is not defined
[2025-02-04T02:43:18.323+0000] {processor.py:811} WARNING - No viable dags retrieved from /opt/airflow/dags/weather_data_dag.py
[2025-02-04T02:43:18.342+0000] {processor.py:178} INFO - Processing /opt/airflow/dags/weather_data_dag.py took 0.042 seconds
[2025-02-04T02:44:35.220+0000] {processor.py:156} INFO - Started process (PID=22) to work on /opt/airflow/dags/weather_data_dag.py
[2025-02-04T02:44:35.222+0000] {processor.py:799} INFO - Processing file /opt/airflow/dags/weather_data_dag.py for tasks to queue
[2025-02-04T02:44:35.224+0000] {logging_mixin.py:149} INFO - [2025-02-04T02:44:35.224+0000] {dagbag.py:541} INFO - Filling up the DagBag from /opt/airflow/dags/weather_data_dag.py
[2025-02-04T02:44:35.239+0000] {logging_mixin.py:149} INFO - [2025-02-04T02:44:35.237+0000] {dagbag.py:350} ERROR - Failed to import: /opt/airflow/dags/weather_data_dag.py
Traceback (most recent call last):
  File "/home/airflow/.local/lib/python3.9/site-packages/airflow/models/dagbag.py", line 346, in parse
    loader.exec_module(new_module)
  File "<frozen importlib._bootstrap_external>", line 850, in exec_module
  File "<frozen importlib._bootstrap>", line 228, in _call_with_frames_removed
  File "/opt/airflow/dags/weather_data_dag.py", line 23, in <module>
    python_callable=create_topic_in_kafka
NameError: name 'create_topic_in_kafka' is not defined
[2025-02-04T02:44:35.240+0000] {processor.py:811} WARNING - No viable dags retrieved from /opt/airflow/dags/weather_data_dag.py
[2025-02-04T02:44:35.260+0000] {processor.py:178} INFO - Processing /opt/airflow/dags/weather_data_dag.py took 0.044 seconds
[2025-02-04T02:45:05.430+0000] {processor.py:156} INFO - Started process (PID=23) to work on /opt/airflow/dags/weather_data_dag.py
[2025-02-04T02:45:05.432+0000] {processor.py:799} INFO - Processing file /opt/airflow/dags/weather_data_dag.py for tasks to queue
[2025-02-04T02:45:05.435+0000] {logging_mixin.py:149} INFO - [2025-02-04T02:45:05.434+0000] {dagbag.py:541} INFO - Filling up the DagBag from /opt/airflow/dags/weather_data_dag.py
[2025-02-04T02:45:05.453+0000] {logging_mixin.py:149} INFO - [2025-02-04T02:45:05.450+0000] {dagbag.py:350} ERROR - Failed to import: /opt/airflow/dags/weather_data_dag.py
Traceback (most recent call last):
  File "/home/airflow/.local/lib/python3.9/site-packages/airflow/models/dagbag.py", line 346, in parse
    loader.exec_module(new_module)
  File "<frozen importlib._bootstrap_external>", line 850, in exec_module
  File "<frozen importlib._bootstrap>", line 228, in _call_with_frames_removed
  File "/opt/airflow/dags/weather_data_dag.py", line 23, in <module>
    python_callable=create_topic_in_kafka
NameError: name 'create_topic_in_kafka' is not defined
[2025-02-04T02:45:05.455+0000] {processor.py:811} WARNING - No viable dags retrieved from /opt/airflow/dags/weather_data_dag.py
[2025-02-04T02:45:05.478+0000] {processor.py:178} INFO - Processing /opt/airflow/dags/weather_data_dag.py took 0.052 seconds
[2025-02-04T02:45:35.668+0000] {processor.py:156} INFO - Started process (PID=24) to work on /opt/airflow/dags/weather_data_dag.py
[2025-02-04T02:45:35.671+0000] {processor.py:799} INFO - Processing file /opt/airflow/dags/weather_data_dag.py for tasks to queue
[2025-02-04T02:45:35.673+0000] {logging_mixin.py:149} INFO - [2025-02-04T02:45:35.673+0000] {dagbag.py:541} INFO - Filling up the DagBag from /opt/airflow/dags/weather_data_dag.py
[2025-02-04T02:45:35.689+0000] {logging_mixin.py:149} INFO - [2025-02-04T02:45:35.686+0000] {dagbag.py:350} ERROR - Failed to import: /opt/airflow/dags/weather_data_dag.py
Traceback (most recent call last):
  File "/home/airflow/.local/lib/python3.9/site-packages/airflow/models/dagbag.py", line 346, in parse
    loader.exec_module(new_module)
  File "<frozen importlib._bootstrap_external>", line 850, in exec_module
  File "<frozen importlib._bootstrap>", line 228, in _call_with_frames_removed
  File "/opt/airflow/dags/weather_data_dag.py", line 23, in <module>
    python_callable=create_topic_in_kafka
NameError: name 'create_topic_in_kafka' is not defined
[2025-02-04T02:45:35.691+0000] {processor.py:811} WARNING - No viable dags retrieved from /opt/airflow/dags/weather_data_dag.py
[2025-02-04T02:45:35.719+0000] {processor.py:178} INFO - Processing /opt/airflow/dags/weather_data_dag.py took 0.055 seconds
[2025-02-04T02:46:05.900+0000] {processor.py:156} INFO - Started process (PID=25) to work on /opt/airflow/dags/weather_data_dag.py
[2025-02-04T02:46:05.902+0000] {processor.py:799} INFO - Processing file /opt/airflow/dags/weather_data_dag.py for tasks to queue
[2025-02-04T02:46:05.904+0000] {logging_mixin.py:149} INFO - [2025-02-04T02:46:05.904+0000] {dagbag.py:541} INFO - Filling up the DagBag from /opt/airflow/dags/weather_data_dag.py
[2025-02-04T02:46:05.917+0000] {logging_mixin.py:149} INFO - [2025-02-04T02:46:05.914+0000] {dagbag.py:350} ERROR - Failed to import: /opt/airflow/dags/weather_data_dag.py
Traceback (most recent call last):
  File "/home/airflow/.local/lib/python3.9/site-packages/airflow/models/dagbag.py", line 346, in parse
    loader.exec_module(new_module)
  File "<frozen importlib._bootstrap_external>", line 850, in exec_module
  File "<frozen importlib._bootstrap>", line 228, in _call_with_frames_removed
  File "/opt/airflow/dags/weather_data_dag.py", line 23, in <module>
    python_callable=create_topic_in_kafka
NameError: name 'create_topic_in_kafka' is not defined
[2025-02-04T02:46:05.918+0000] {processor.py:811} WARNING - No viable dags retrieved from /opt/airflow/dags/weather_data_dag.py
[2025-02-04T02:46:05.943+0000] {processor.py:178} INFO - Processing /opt/airflow/dags/weather_data_dag.py took 0.047 seconds
[2025-02-04T02:46:36.143+0000] {processor.py:156} INFO - Started process (PID=26) to work on /opt/airflow/dags/weather_data_dag.py
[2025-02-04T02:46:36.146+0000] {processor.py:799} INFO - Processing file /opt/airflow/dags/weather_data_dag.py for tasks to queue
[2025-02-04T02:46:36.147+0000] {logging_mixin.py:149} INFO - [2025-02-04T02:46:36.147+0000] {dagbag.py:541} INFO - Filling up the DagBag from /opt/airflow/dags/weather_data_dag.py
[2025-02-04T02:46:36.162+0000] {logging_mixin.py:149} INFO - [2025-02-04T02:46:36.160+0000] {dagbag.py:350} ERROR - Failed to import: /opt/airflow/dags/weather_data_dag.py
Traceback (most recent call last):
  File "/home/airflow/.local/lib/python3.9/site-packages/airflow/models/dagbag.py", line 346, in parse
    loader.exec_module(new_module)
  File "<frozen importlib._bootstrap_external>", line 850, in exec_module
  File "<frozen importlib._bootstrap>", line 228, in _call_with_frames_removed
  File "/opt/airflow/dags/weather_data_dag.py", line 23, in <module>
    python_callable=create_topic_in_kafka
NameError: name 'create_topic_in_kafka' is not defined
[2025-02-04T02:46:36.163+0000] {processor.py:811} WARNING - No viable dags retrieved from /opt/airflow/dags/weather_data_dag.py
[2025-02-04T02:46:36.181+0000] {processor.py:178} INFO - Processing /opt/airflow/dags/weather_data_dag.py took 0.042 seconds
[2025-02-04T02:47:06.397+0000] {processor.py:156} INFO - Started process (PID=27) to work on /opt/airflow/dags/weather_data_dag.py
[2025-02-04T02:47:06.401+0000] {processor.py:799} INFO - Processing file /opt/airflow/dags/weather_data_dag.py for tasks to queue
[2025-02-04T02:47:06.384+0000] {logging_mixin.py:149} INFO - [2025-02-04T02:47:06.384+0000] {dagbag.py:541} INFO - Filling up the DagBag from /opt/airflow/dags/weather_data_dag.py
[2025-02-04T02:47:06.414+0000] {logging_mixin.py:149} INFO - [2025-02-04T02:47:06.410+0000] {dagbag.py:350} ERROR - Failed to import: /opt/airflow/dags/weather_data_dag.py
Traceback (most recent call last):
  File "/home/airflow/.local/lib/python3.9/site-packages/airflow/models/dagbag.py", line 346, in parse
    loader.exec_module(new_module)
  File "<frozen importlib._bootstrap_external>", line 850, in exec_module
  File "<frozen importlib._bootstrap>", line 228, in _call_with_frames_removed
  File "/opt/airflow/dags/weather_data_dag.py", line 23, in <module>
    python_callable=create_topic_in_kafka
NameError: name 'create_topic_in_kafka' is not defined
[2025-02-04T02:47:06.416+0000] {processor.py:811} WARNING - No viable dags retrieved from /opt/airflow/dags/weather_data_dag.py
[2025-02-04T02:47:06.453+0000] {processor.py:178} INFO - Processing /opt/airflow/dags/weather_data_dag.py took 0.088 seconds
[2025-02-04T02:47:36.576+0000] {processor.py:156} INFO - Started process (PID=28) to work on /opt/airflow/dags/weather_data_dag.py
[2025-02-04T02:47:36.578+0000] {processor.py:799} INFO - Processing file /opt/airflow/dags/weather_data_dag.py for tasks to queue
[2025-02-04T02:47:36.580+0000] {logging_mixin.py:149} INFO - [2025-02-04T02:47:36.579+0000] {dagbag.py:541} INFO - Filling up the DagBag from /opt/airflow/dags/weather_data_dag.py
[2025-02-04T02:47:36.593+0000] {logging_mixin.py:149} INFO - [2025-02-04T02:47:36.591+0000] {dagbag.py:350} ERROR - Failed to import: /opt/airflow/dags/weather_data_dag.py
Traceback (most recent call last):
  File "/home/airflow/.local/lib/python3.9/site-packages/airflow/models/dagbag.py", line 346, in parse
    loader.exec_module(new_module)
  File "<frozen importlib._bootstrap_external>", line 850, in exec_module
  File "<frozen importlib._bootstrap>", line 228, in _call_with_frames_removed
  File "/opt/airflow/dags/weather_data_dag.py", line 23, in <module>
    python_callable=create_topic_in_kafka
NameError: name 'create_topic_in_kafka' is not defined
[2025-02-04T02:47:36.594+0000] {processor.py:811} WARNING - No viable dags retrieved from /opt/airflow/dags/weather_data_dag.py
[2025-02-04T02:47:36.614+0000] {processor.py:178} INFO - Processing /opt/airflow/dags/weather_data_dag.py took 0.042 seconds
[2025-02-04T02:48:06.808+0000] {processor.py:156} INFO - Started process (PID=29) to work on /opt/airflow/dags/weather_data_dag.py
[2025-02-04T02:48:06.811+0000] {processor.py:799} INFO - Processing file /opt/airflow/dags/weather_data_dag.py for tasks to queue
[2025-02-04T02:48:06.812+0000] {logging_mixin.py:149} INFO - [2025-02-04T02:48:06.812+0000] {dagbag.py:541} INFO - Filling up the DagBag from /opt/airflow/dags/weather_data_dag.py
[2025-02-04T02:48:06.827+0000] {logging_mixin.py:149} INFO - [2025-02-04T02:48:06.825+0000] {dagbag.py:350} ERROR - Failed to import: /opt/airflow/dags/weather_data_dag.py
Traceback (most recent call last):
  File "/home/airflow/.local/lib/python3.9/site-packages/airflow/models/dagbag.py", line 346, in parse
    loader.exec_module(new_module)
  File "<frozen importlib._bootstrap_external>", line 850, in exec_module
  File "<frozen importlib._bootstrap>", line 228, in _call_with_frames_removed
  File "/opt/airflow/dags/weather_data_dag.py", line 23, in <module>
    python_callable=create_topic_in_kafka
NameError: name 'create_topic_in_kafka' is not defined
[2025-02-04T02:48:06.828+0000] {processor.py:811} WARNING - No viable dags retrieved from /opt/airflow/dags/weather_data_dag.py
[2025-02-04T02:48:06.847+0000] {processor.py:178} INFO - Processing /opt/airflow/dags/weather_data_dag.py took 0.042 seconds
[2025-02-04T02:49:28.058+0000] {processor.py:156} INFO - Started process (PID=23) to work on /opt/airflow/dags/weather_data_dag.py
[2025-02-04T02:49:28.061+0000] {processor.py:799} INFO - Processing file /opt/airflow/dags/weather_data_dag.py for tasks to queue
[2025-02-04T02:49:28.063+0000] {logging_mixin.py:149} INFO - [2025-02-04T02:49:28.063+0000] {dagbag.py:541} INFO - Filling up the DagBag from /opt/airflow/dags/weather_data_dag.py
[2025-02-04T02:49:28.077+0000] {logging_mixin.py:149} INFO - [2025-02-04T02:49:28.075+0000] {dagbag.py:350} ERROR - Failed to import: /opt/airflow/dags/weather_data_dag.py
Traceback (most recent call last):
  File "/home/airflow/.local/lib/python3.9/site-packages/airflow/models/dagbag.py", line 346, in parse
    loader.exec_module(new_module)
  File "<frozen importlib._bootstrap_external>", line 850, in exec_module
  File "<frozen importlib._bootstrap>", line 228, in _call_with_frames_removed
  File "/opt/airflow/dags/weather_data_dag.py", line 23, in <module>
    python_callable=create_topic_in_kafka
NameError: name 'create_topic_in_kafka' is not defined
[2025-02-04T02:49:28.079+0000] {processor.py:811} WARNING - No viable dags retrieved from /opt/airflow/dags/weather_data_dag.py
[2025-02-04T02:49:28.100+0000] {processor.py:178} INFO - Processing /opt/airflow/dags/weather_data_dag.py took 0.046 seconds
[2025-02-04T02:49:59.140+0000] {processor.py:156} INFO - Started process (PID=24) to work on /opt/airflow/dags/weather_data_dag.py
[2025-02-04T02:49:59.142+0000] {processor.py:799} INFO - Processing file /opt/airflow/dags/weather_data_dag.py for tasks to queue
[2025-02-04T02:49:59.144+0000] {logging_mixin.py:149} INFO - [2025-02-04T02:49:59.143+0000] {dagbag.py:541} INFO - Filling up the DagBag from /opt/airflow/dags/weather_data_dag.py
[2025-02-04T02:49:59.157+0000] {logging_mixin.py:149} INFO - [2025-02-04T02:49:59.155+0000] {dagbag.py:350} ERROR - Failed to import: /opt/airflow/dags/weather_data_dag.py
Traceback (most recent call last):
  File "/home/airflow/.local/lib/python3.9/site-packages/airflow/models/dagbag.py", line 346, in parse
    loader.exec_module(new_module)
  File "<frozen importlib._bootstrap_external>", line 850, in exec_module
  File "<frozen importlib._bootstrap>", line 228, in _call_with_frames_removed
  File "/opt/airflow/dags/weather_data_dag.py", line 23, in <module>
    python_callable=create_topic_in_kafka
NameError: name 'create_topic_in_kafka' is not defined
[2025-02-04T02:49:59.159+0000] {processor.py:811} WARNING - No viable dags retrieved from /opt/airflow/dags/weather_data_dag.py
[2025-02-04T02:49:59.180+0000] {processor.py:178} INFO - Processing /opt/airflow/dags/weather_data_dag.py took 0.044 seconds
[2025-02-04T02:52:20.995+0000] {processor.py:156} INFO - Started process (PID=21) to work on /opt/airflow/dags/weather_data_dag.py
[2025-02-04T02:52:20.998+0000] {processor.py:799} INFO - Processing file /opt/airflow/dags/weather_data_dag.py for tasks to queue
[2025-02-04T02:52:20.999+0000] {logging_mixin.py:149} INFO - [2025-02-04T02:52:20.999+0000] {dagbag.py:541} INFO - Filling up the DagBag from /opt/airflow/dags/weather_data_dag.py
[2025-02-04T02:52:21.014+0000] {logging_mixin.py:149} INFO - [2025-02-04T02:52:21.011+0000] {dagbag.py:350} ERROR - Failed to import: /opt/airflow/dags/weather_data_dag.py
Traceback (most recent call last):
  File "/home/airflow/.local/lib/python3.9/site-packages/airflow/models/dagbag.py", line 346, in parse
    loader.exec_module(new_module)
  File "<frozen importlib._bootstrap_external>", line 850, in exec_module
  File "<frozen importlib._bootstrap>", line 228, in _call_with_frames_removed
  File "/opt/airflow/dags/weather_data_dag.py", line 23, in <module>
    python_callable=create_topic_in_kafka
NameError: name 'create_topic_in_kafka' is not defined
[2025-02-04T02:52:21.015+0000] {processor.py:811} WARNING - No viable dags retrieved from /opt/airflow/dags/weather_data_dag.py
[2025-02-04T02:52:21.037+0000] {processor.py:178} INFO - Processing /opt/airflow/dags/weather_data_dag.py took 0.045 seconds
[2025-02-04T02:52:51.148+0000] {processor.py:156} INFO - Started process (PID=22) to work on /opt/airflow/dags/weather_data_dag.py
[2025-02-04T02:52:51.150+0000] {processor.py:799} INFO - Processing file /opt/airflow/dags/weather_data_dag.py for tasks to queue
[2025-02-04T02:52:51.151+0000] {logging_mixin.py:149} INFO - [2025-02-04T02:52:51.151+0000] {dagbag.py:541} INFO - Filling up the DagBag from /opt/airflow/dags/weather_data_dag.py
[2025-02-04T02:52:51.167+0000] {logging_mixin.py:149} INFO - [2025-02-04T02:52:51.165+0000] {dagbag.py:350} ERROR - Failed to import: /opt/airflow/dags/weather_data_dag.py
Traceback (most recent call last):
  File "/home/airflow/.local/lib/python3.9/site-packages/airflow/models/dagbag.py", line 346, in parse
    loader.exec_module(new_module)
  File "<frozen importlib._bootstrap_external>", line 850, in exec_module
  File "<frozen importlib._bootstrap>", line 228, in _call_with_frames_removed
  File "/opt/airflow/dags/weather_data_dag.py", line 23, in <module>
    python_callable=create_topic_in_kafka
NameError: name 'create_topic_in_kafka' is not defined
[2025-02-04T02:52:51.169+0000] {processor.py:811} WARNING - No viable dags retrieved from /opt/airflow/dags/weather_data_dag.py
[2025-02-04T02:52:51.194+0000] {processor.py:178} INFO - Processing /opt/airflow/dags/weather_data_dag.py took 0.052 seconds
[2025-02-04T02:52:52.313+0000] {processor.py:156} INFO - Started process (PID=23) to work on /opt/airflow/dags/weather_data_dag.py
[2025-02-04T02:52:52.314+0000] {processor.py:799} INFO - Processing file /opt/airflow/dags/weather_data_dag.py for tasks to queue
[2025-02-04T02:52:52.316+0000] {logging_mixin.py:149} INFO - [2025-02-04T02:52:52.315+0000] {dagbag.py:541} INFO - Filling up the DagBag from /opt/airflow/dags/weather_data_dag.py
[2025-02-04T02:52:52.326+0000] {processor.py:811} WARNING - No viable dags retrieved from /opt/airflow/dags/weather_data_dag.py
[2025-02-04T02:52:52.342+0000] {processor.py:178} INFO - Processing /opt/airflow/dags/weather_data_dag.py took 0.033 seconds
[2025-02-04T02:53:22.664+0000] {processor.py:156} INFO - Started process (PID=24) to work on /opt/airflow/dags/weather_data_dag.py
[2025-02-04T02:53:22.666+0000] {processor.py:799} INFO - Processing file /opt/airflow/dags/weather_data_dag.py for tasks to queue
[2025-02-04T02:53:22.668+0000] {logging_mixin.py:149} INFO - [2025-02-04T02:53:22.668+0000] {dagbag.py:541} INFO - Filling up the DagBag from /opt/airflow/dags/weather_data_dag.py
[2025-02-04T02:53:22.675+0000] {processor.py:811} WARNING - No viable dags retrieved from /opt/airflow/dags/weather_data_dag.py
[2025-02-04T02:53:22.688+0000] {processor.py:178} INFO - Processing /opt/airflow/dags/weather_data_dag.py took 0.027 seconds
