[2025-02-07T06:10:51.613+0000] {taskinstance.py:1125} INFO - Dependencies all met for dep_context=non-requeueable deps ti=<TaskInstance: get_current_weather.transform_raw_data manual__2025-02-07T06:10:26.444275+00:00 [queued]>
[2025-02-07T06:10:51.627+0000] {taskinstance.py:1125} INFO - Dependencies all met for dep_context=requeueable deps ti=<TaskInstance: get_current_weather.transform_raw_data manual__2025-02-07T06:10:26.444275+00:00 [queued]>
[2025-02-07T06:10:51.629+0000] {taskinstance.py:1331} INFO - Starting attempt 1 of 1
[2025-02-07T06:10:51.645+0000] {taskinstance.py:1350} INFO - Executing <Task(PythonOperator): transform_raw_data> on 2025-02-07 06:10:26.444275+00:00
[2025-02-07T06:10:51.652+0000] {standard_task_runner.py:57} INFO - Started process 149 to run task
[2025-02-07T06:10:51.657+0000] {standard_task_runner.py:84} INFO - Running: ['***', 'tasks', 'run', 'get_current_weather', 'transform_raw_data', 'manual__2025-02-07T06:10:26.444275+00:00', '--job-id', '6', '--raw', '--subdir', 'DAGS_FOLDER/weather_data_dag.py', '--cfg-path', '/tmp/tmpf_jepp5k']
[2025-02-07T06:10:51.660+0000] {standard_task_runner.py:85} INFO - Job 6: Subtask transform_raw_data
[2025-02-07T06:10:51.759+0000] {task_command.py:410} INFO - Running <TaskInstance: get_current_weather.transform_raw_data manual__2025-02-07T06:10:26.444275+00:00 [running]> on host 5a15db971c3c
[2025-02-07T06:10:52.061+0000] {taskinstance.py:1568} INFO - Exporting env vars: AIRFLOW_CTX_DAG_OWNER='airscholar' AIRFLOW_CTX_DAG_ID='get_current_weather' AIRFLOW_CTX_TASK_ID='transform_raw_data' AIRFLOW_CTX_EXECUTION_DATE='2025-02-07T06:10:26.444275+00:00' AIRFLOW_CTX_TRY_NUMBER='1' AIRFLOW_CTX_DAG_RUN_ID='manual__2025-02-07T06:10:26.444275+00:00'
[2025-02-07T06:10:52.065+0000] {taskinstance.py:1847} ERROR - Task failed with exception
Traceback (most recent call last):
  File "/home/airflow/.local/lib/python3.9/site-packages/airflow/operators/python.py", line 181, in execute
    return_value = self.execute_callable()
  File "/home/airflow/.local/lib/python3.9/site-packages/airflow/operators/python.py", line 198, in execute_callable
    return self.python_callable(*self.op_args, **self.op_kwargs)
TypeError: transform() missing 1 required positional argument: 'df'
[2025-02-07T06:10:52.086+0000] {taskinstance.py:1368} INFO - Marking task as FAILED. dag_id=get_current_weather, task_id=transform_raw_data, execution_date=20250207T061026, start_date=20250207T061051, end_date=20250207T061052
[2025-02-07T06:10:52.109+0000] {standard_task_runner.py:104} ERROR - Failed to execute job 6 for task transform_raw_data (transform() missing 1 required positional argument: 'df'; 149)
[2025-02-07T06:10:52.154+0000] {local_task_job_runner.py:232} INFO - Task exited with return code 1
[2025-02-07T06:10:52.191+0000] {taskinstance.py:2674} INFO - 0 downstream tasks scheduled from follow-on schedule check
