[2025-02-15T01:36:46.532+0000] {taskinstance.py:1125} INFO - Dependencies all met for dep_context=non-requeueable deps ti=<TaskInstance: weather_data_ETL.transform_alerts manual__2025-02-15T00:56:13.638531+00:00 [queued]>
[2025-02-15T01:36:46.547+0000] {taskinstance.py:1125} INFO - Dependencies all met for dep_context=requeueable deps ti=<TaskInstance: weather_data_ETL.transform_alerts manual__2025-02-15T00:56:13.638531+00:00 [queued]>
[2025-02-15T01:36:46.548+0000] {taskinstance.py:1331} INFO - Starting attempt 4 of 4
[2025-02-15T01:36:46.566+0000] {taskinstance.py:1350} INFO - Executing <Task(PythonOperator): transform_alerts> on 2025-02-15 00:56:13.638531+00:00
[2025-02-15T01:36:46.573+0000] {standard_task_runner.py:57} INFO - Started process 104 to run task
[2025-02-15T01:36:46.579+0000] {standard_task_runner.py:84} INFO - Running: ['***', 'tasks', 'run', 'weather_data_ETL', 'transform_alerts', 'manual__2025-02-15T00:56:13.638531+00:00', '--job-id', '76', '--raw', '--subdir', 'DAGS_FOLDER/weather_dag.py', '--cfg-path', '/tmp/tmp9mav3dk5']
[2025-02-15T01:36:46.582+0000] {standard_task_runner.py:85} INFO - Job 76: Subtask transform_alerts
[2025-02-15T01:36:46.713+0000] {task_command.py:410} INFO - Running <TaskInstance: weather_data_ETL.transform_alerts manual__2025-02-15T00:56:13.638531+00:00 [running]> on host 184396a03990
[2025-02-15T01:36:46.925+0000] {taskinstance.py:1568} INFO - Exporting env vars: AIRFLOW_CTX_DAG_OWNER='airscholar' AIRFLOW_CTX_DAG_ID='weather_data_ETL' AIRFLOW_CTX_TASK_ID='transform_alerts' AIRFLOW_CTX_EXECUTION_DATE='2025-02-15T00:56:13.638531+00:00' AIRFLOW_CTX_TRY_NUMBER='4' AIRFLOW_CTX_DAG_RUN_ID='manual__2025-02-15T00:56:13.638531+00:00'
[2025-02-15T01:36:47.013+0000] {taskinstance.py:1847} ERROR - Task failed with exception
Traceback (most recent call last):
  File "/home/airflow/.local/lib/python3.9/site-packages/airflow/operators/python.py", line 181, in execute
    return_value = self.execute_callable()
  File "/home/airflow/.local/lib/python3.9/site-packages/airflow/operators/python.py", line 198, in execute_callable
    return self.python_callable(*self.op_args, **self.op_kwargs)
  File "/opt/airflow/dags/transform_weather.py", line 55, in transform_alerts
    alert = get_alerts(response)
  File "/opt/airflow/dags/transform_weather.py", line 128, in get_alerts
    alerts = response['alerts']
KeyError: 'alerts'
[2025-02-15T01:36:47.044+0000] {taskinstance.py:1368} INFO - Marking task as FAILED. dag_id=weather_data_ETL, task_id=transform_alerts, execution_date=20250215T005613, start_date=20250215T013646, end_date=20250215T013647
[2025-02-15T01:36:47.085+0000] {standard_task_runner.py:104} ERROR - Failed to execute job 76 for task transform_alerts ('alerts'; 104)
[2025-02-15T01:36:47.117+0000] {local_task_job_runner.py:232} INFO - Task exited with return code 1
[2025-02-15T01:36:47.171+0000] {taskinstance.py:2674} INFO - 0 downstream tasks scheduled from follow-on schedule check
