[2025-02-15T01:31:43.275+0000] {taskinstance.py:1125} INFO - Dependencies all met for dep_context=non-requeueable deps ti=<TaskInstance: weather_data_ETL.transform_alerts manual__2025-02-15T00:56:13.638531+00:00 [queued]>
[2025-02-15T01:31:43.293+0000] {taskinstance.py:1125} INFO - Dependencies all met for dep_context=requeueable deps ti=<TaskInstance: weather_data_ETL.transform_alerts manual__2025-02-15T00:56:13.638531+00:00 [queued]>
[2025-02-15T01:31:43.295+0000] {taskinstance.py:1331} INFO - Starting attempt 2 of 2
[2025-02-15T01:31:43.315+0000] {taskinstance.py:1350} INFO - Executing <Task(PythonOperator): transform_alerts> on 2025-02-15 00:56:13.638531+00:00
[2025-02-15T01:31:43.323+0000] {standard_task_runner.py:57} INFO - Started process 42 to run task
[2025-02-15T01:31:43.327+0000] {standard_task_runner.py:84} INFO - Running: ['***', 'tasks', 'run', 'weather_data_ETL', 'transform_alerts', 'manual__2025-02-15T00:56:13.638531+00:00', '--job-id', '74', '--raw', '--subdir', 'DAGS_FOLDER/weather_dag.py', '--cfg-path', '/tmp/tmp3yyog0xn']
[2025-02-15T01:31:43.331+0000] {standard_task_runner.py:85} INFO - Job 74: Subtask transform_alerts
[2025-02-15T01:31:43.449+0000] {task_command.py:410} INFO - Running <TaskInstance: weather_data_ETL.transform_alerts manual__2025-02-15T00:56:13.638531+00:00 [running]> on host 184396a03990
[2025-02-15T01:31:43.650+0000] {taskinstance.py:1568} INFO - Exporting env vars: AIRFLOW_CTX_DAG_OWNER='airscholar' AIRFLOW_CTX_DAG_ID='weather_data_ETL' AIRFLOW_CTX_TASK_ID='transform_alerts' AIRFLOW_CTX_EXECUTION_DATE='2025-02-15T00:56:13.638531+00:00' AIRFLOW_CTX_TRY_NUMBER='2' AIRFLOW_CTX_DAG_RUN_ID='manual__2025-02-15T00:56:13.638531+00:00'
[2025-02-15T01:31:43.745+0000] {taskinstance.py:1847} ERROR - Task failed with exception
Traceback (most recent call last):
  File "/home/airflow/.local/lib/python3.9/site-packages/airflow/operators/python.py", line 181, in execute
    return_value = self.execute_callable()
  File "/home/airflow/.local/lib/python3.9/site-packages/airflow/operators/python.py", line 198, in execute_callable
    return self.python_callable(*self.op_args, **self.op_kwargs)
  File "/opt/airflow/dags/transform_weather.py", line 55, in transform_alerts
    a = get_alerts(response)
  File "/opt/airflow/dags/transform_weather.py", line 132, in get_alerts
    data = {key: alerts_cols(alert.get(key, 0)) for key in alerts_cols}
  File "/opt/airflow/dags/transform_weather.py", line 132, in <dictcomp>
    data = {key: alerts_cols(alert.get(key, 0)) for key in alerts_cols}
TypeError: 'dict' object is not callable
[2025-02-15T01:31:43.779+0000] {taskinstance.py:1368} INFO - Marking task as FAILED. dag_id=weather_data_ETL, task_id=transform_alerts, execution_date=20250215T005613, start_date=20250215T013143, end_date=20250215T013143
[2025-02-15T01:31:43.817+0000] {standard_task_runner.py:104} ERROR - Failed to execute job 74 for task transform_alerts ('dict' object is not callable; 42)
[2025-02-15T01:31:43.863+0000] {local_task_job_runner.py:232} INFO - Task exited with return code 1
[2025-02-15T01:31:43.913+0000] {taskinstance.py:2674} INFO - 0 downstream tasks scheduled from follow-on schedule check
